Workbook
Name L_Customers: '23_SETTINGS'!$H$9:$H$2788
Name L_Status: '23_SETTINGS'!$A$11:$A$15
Name L_RAG: '23_SETTINGS'!$B$11:$B$13
Name L_Priority: '23_SETTINGS'!$C$11:$C$14
Name L_HML: '23_SETTINGS'!$D$11:$D$13
Name L_Prob: '23_SETTINGS'!$E$11:$E$14
Name L_Impact: '23_SETTINGS'!$F$11:$F$14
Name L_RAIDType: '23_SETTINGS'!$A$18:$A$21
Name L_RAIDStatus: '23_SETTINGS'!$B$18:$B$20
Name L_RAIDCategory: '23_SETTINGS'!$C$18:$C$27
Name L_ActionStatus: '23_SETTINGS'!$D$18:$D$21
Name L_ChangeStatus: '23_SETTINGS'!$E$18:$E$20
Name L_ImplStatus: '23_SETTINGS'!$F$18:$F$21
Name L_MilestoneStatus: '23_SETTINGS'!$A$30:$A$34
Name L_TaskStatus: '23_SETTINGS'!$B$30:$B$33
Name L_Dept: '23_SETTINGS'!$C$30:$C$37
Name L_ProjType: '23_SETTINGS'!$D$30:$D$35
Name L_Owner: '23_SETTINGS'!$E$30:$E$37
Name L_Engagement: '23_SETTINGS'!$F$30:$F$34
Name L_Frequency: '23_SETTINGS'!$A$40:$A$46
Name L_YesNo: '23_SETTINGS'!$B$40:$B$41
Name L_RACI: '23_SETTINGS'!$C$40:$C$43
Name L_CostCategory: '23_SETTINGS'!$D$40:$D$47
Name L_ProcStatus: '23_SETTINGS'!$E$40:$E$45
Name L_QualityResult: '23_SETTINGS'!$F$40:$F$43
Name L_MeetingType: '23_SETTINGS'!$A$50:$A$55
Name L_DecisionStatus: '23_SETTINGS'!$B$50:$B$53
Name L_ClosureStatus: '23_SETTINGS'!$C$50:$C$53
Name L_LessonArea: '23_SETTINGS'!$D$50:$D$60
Name L_Channel: '23_SETTINGS'!$E$50:$E$55
Name L_Format: '23_SETTINGS'!$F$50:$F$54
Name L_FilterStatus: '23_SETTINGS'!$A$63:$A$68
Name L_FilterRAG: '23_SETTINGS'!$B$63:$B$66
Name L_FilterMgr: '23_SETTINGS'!$C$63:$C$71
Name L_Projects: '02_PROJECT_PORTFOLIO'!$C$5:$C$34

Sheet 00_HOME
A1: ASSISTANT PMO - MANAGEMENT SYSTEM
A2: Control centre for the portfolio: click any tile to open a sheet, then use the dashboards to brief management.
A3: Nothing here needs typing except the registers themselves - every tile, KPI, chart and count in this workbook is a formula or a hyperlink.
A4: ="PMO CONTROL CENTRE | "&TEXT(TODAY(),"dddd, dd mmmm yyyy")&" | "&COUNTIF('02_PROJECT_PORTFOLIO'!$C$5:$C$34,"?*")&" PROJECTS | "&COUNTIFS('06_RAID_LOG'!$C$5:$C$34,"Risk",'06_RAID_LOG'!$N$5:$N$34,"<>Closed")&" OPEN RISKS | "&COUNTIF('07_ACTION_TRACKER'!$K$5:$K$34,">0")&" OVERDUE ACTIONS | "&COUNTIF('17_DECISION_LOG'!$L$5:$L$34,"Pending")&" DECISIONS PENDING"
A6: NAVIGATION - CLICK ANY TILE TO OPEN THAT SHEET
A7: =HYPERLINK("#'01_EXECUTIVE_DASHBOARD'!A1","01 EXECUTIVE DASHBOARD") | C7: =HYPERLINK("#'01B_PROJECT_DASHBOARD'!A1","01B PROJECT DASHBOARD") | E7: =HYPERLINK("#'02_PROJECT_PORTFOLIO'!A1","02 PROJECT PORTFOLIO") | G7: =HYPERLINK("#'03_PROJECT_CHARTER'!A1","03 PROJECT CHARTER") | I7: =HYPERLINK("#'04_WBS_SCHEDULE'!A1","04 WBS & GANTT") | K7: QUICK STATUS
A8: =HYPERLINK("#'05_MILESTONES'!A1","05 MILESTONES") | C8: =HYPERLINK("#'06_RAID_LOG'!A1","06 RAID LOG") | E8: =HYPERLINK("#'07_ACTION_TRACKER'!A1","07 ACTION TRACKER") | G8: =HYPERLINK("#'08_RACI_MATRIX'!A1","08 RACI MATRIX") | I8: =HYPERLINK("#'09_STAKEHOLDERS'!A1","09 STAKEHOLDERS") | K8: =COUNTIF('02_PROJECT_PORTFOLIO'!$C$5:$C$34,"?*")&" projects in portfolio"
A9: =HYPERLINK("#'10_CHANGE_CONTROL'!A1","10 CHANGE CONTROL") | C9: =HYPERLINK("#'11_COST_MANAGEMENT'!A1","11 COST MANAGEMENT") | E9: =HYPERLINK("#'12_RESOURCE_MANAGEMENT'!A1","12 RESOURCE MANAGEMENT") | G9: =HYPERLINK("#'13_PROCUREMENT'!A1","13 PROCUREMENT") | I9: =HYPERLINK("#'14_QUALITY_CONTROL'!A1","14 QUALITY CONTROL") | K9: =COUNTIFS('06_RAID_LOG'!$C$5:$C$34,"Risk",'06_RAID_LOG'!$N$5:$N$34,"<>Closed")&" open risks"
A10: =HYPERLINK("#'15_WEEKLY_STATUS'!A1","15 WEEKLY STATUS") | C10: =HYPERLINK("#'16_MEETING_MINUTES'!A1","16 MEETING MINUTES") | E10: =HYPERLINK("#'17_DECISION_LOG'!A1","17 DECISION LOG") | G10: =HYPERLINK("#'18_COMMUNICATION_PLAN'!A1","18 COMMUNICATION PLAN") | I10: =HYPERLINK("#'19_PROJECT_CLOSURE'!A1","19 PROJECT CLOSURE") | K10: =COUNTIF('07_ACTION_TRACKER'!$K$5:$K$34,">0")&" overdue actions"
A11: =HYPERLINK("#'20_LESSONS_LEARNED'!A1","20 LESSONS LEARNED") | C11: =HYPERLINK("#'21_PMOSOP'!A1","21 PMO SOP") | E11: =HYPERLINK("#'22_30_60_90_PLAN'!A1","22 30 / 60 / 90 PLAN") | G11: =HYPERLINK("#'23_SETTINGS'!A1","23 SETTINGS") | I11: =HYPERLINK("#'24_DATA_DICTIONARY'!A1","24 DATA DICTIONARY") | K11: =COUNTIF('17_DECISION_LOG'!$L$5:$L$34,"Pending")&" decisions pending"
A13: HOW THIS WORKBOOK IS ORGANISED
A14: GOVERNANCE 03 Project Charter | 08 RACI Matrix | 09 Stakeholders | 10 Change Control | 17 Decision Log | 18 Communication Plan
A15: DELIVERY 02 Project Portfolio | 04 WBS & Gantt | 05 Milestones | 07 Action Tracker | 12 Resources | 13 Procurement | 14 Quality | 22 30-60-90 Plan
A16: CONTROL 06 RAID Log | 11 Cost Management | 15 Weekly Status | 16 Meeting Minutes | 19 Project Closure | 20 Lessons Learned | 21 PMO SOP
A17: REPORTING 01 Executive Dashboard | 01B Project Dashboard | 23 Settings | 24 Data Dictionary
A19: TODAY'S PRIORITIES - READ THIS BEFORE THE MANAGEMENT MEETING
A20: ="1. "&COUNTIF('07_ACTION_TRACKER'!$K$5:$K$34,">0")&" actions overdue (worst "&MAX('07_ACTION_TRACKER'!$K$5:$K$34)&" days) - open 07_ACTION_TRACKER"
A21: ="2. "&COUNTIFS('05_MILESTONES'!$F$5:$F$34,">0",'05_MILESTONES'!$F$5:$F$34,"<"&TODAY(),'05_MILESTONES'!$H$5:$H$34,"<>Complete")&" milestones overdue - open 05_MILESTONES"
A22: ="3. "&COUNTIFS('06_RAID_LOG'!$C$5:$C$34,"Risk",'06_RAID_LOG'!$I$5:$I$34,"Critical",'06_RAID_LOG'!$N$5:$N$34,"<>Closed")&" critical risks open - open 06_RAID_LOG"
A23: ="4. "&COUNTIF('10_CHANGE_CONTROL'!$N$5:$N$34,"Pending")&" change requests awaiting approval - open 10_CHANGE_CONTROL"
A24: ="5. "&COUNTIF('17_DECISION_LOG'!$L$5:$L$34,"Pending")&" decisions pending - open 17_DECISION_LOG"
A26: EVERYTHING IS AUTOMATIC: drop-downs come from 23_SETTINGS, KPIs and charts come from the registers, and the dashboards refresh the moment a register changes. Sample records are marked SAMPLE in their Notes column - delete them whenever you like.

Sheet 01_EXECUTIVE_DASHBOARD
A1: EXECUTIVE DASHBOARD | P1: AUTOMATIC CHART DATA - FORMULAS ONLY, DO NOT EDIT
A2: Live portfolio control panel: 14 KPIs, management attention panels, next milestones, a filterable portfolio view and 10 charts - every figure is a formula.
A3: All values calculate from the registers (portfolio, RAID, actions, milestones, changes, decisions). Change a register and this sheet updates automatically. | P3: BLOCK 1 - PROJECT STATUS
A4: ="PORTFOLIO: "&A6&" PROJECTS | ACTIVE: "&C6&" | ON TRACK: "&E6&" | AT RISK: "&G6&" | DELAYED: "&I6&" | OPEN RISKS: "&M6&" | OVERDUE ACTIONS: "&C10&" | DECISIONS PENDING: "&M10&" | AS AT "&TEXT(TODAY(),"DD MMM YYYY") | P4: Status | Q4: Projects
A5: TOTAL PROJECTS | C5: ACTIVE PROJECTS | E5: ON TRACK | G5: AT RISK | I5: DELAYED | K5: COMPLETED | M5: OPEN RISKS | P5: Not Started | Q5: =COUNTIF('02_PROJECT_PORTFOLIO'!$M$5:$M$34,P5)
A6: =COUNTIF('02_PROJECT_PORTFOLIO'!$C$5:$C$34,"?*") | C6: =COUNTIF('02_PROJECT_PORTFOLIO'!$M$5:$M$34,"Active") | E6: =COUNTIFS('02_PROJECT_PORTFOLIO'!$N$5:$N$34,"Green",'02_PROJECT_PORTFOLIO'!$M$5:$M$34,"<>Completed",'02_PROJECT_PORTFOLIO'!$M$5:$M$34,"<>Cancelled") | G6: =COUNTIF('02_PROJECT_PORTFOLIO'!$N$5:$N$34,"Yellow") | I6: =COUNTIF('02_PROJECT_PORTFOLIO'!$N$5:$N$34,"Red") | K6: =COUNTIF('02_PROJECT_PORTFOLIO'!$M$5:$M$34,"Completed") | M6: =COUNTIFS('06_RAID_LOG'!$C$5:$C$34,"Risk",'06_RAID_LOG'!$N$5:$N$34,"<>Closed") | P6: Active | Q6: =COUNTIF('02_PROJECT_PORTFOLIO'!$M$5:$M$34,P6)
A7: REGISTERED IN PORTFOLIO | C7: =TEXT(IFERROR(C6/A6,0),"0%")&" OF PORTFOLIO" | E7: GREEN RAG, IN FLIGHT | G7: YELLOW RAG - WATCH | I7: RED RAG - ACT NOW | K7: CLOSED / IN CLOSURE | M7: ="CRITICAL: "&COUNTIFS('06_RAID_LOG'!$C$5:$C$34,"Risk",'06_RAID_LOG'!$I$5:$I$34,"Critical",'06_RAID_LOG'!$N$5:$N$34,"<>Closed") | P7: On Hold | Q7: =COUNTIF('02_PROJECT_PORTFOLIO'!$M$5:$M$34,P7)
P8: Completed | Q8: =COUNTIF('02_PROJECT_PORTFOLIO'!$M$5:$M$34,P8)
A9: OPEN ISSUES | C9: OVERDUE ACTIONS | E9: APPROVED AMOUNT | G9: ACTUAL COST | I9: FORECAST COST | K9: MILESTONES DUE 7 DAYS | M9: PENDING DECISIONS | P9: Cancelled | Q9: =COUNTIF('02_PROJECT_PORTFOLIO'!$M$5:$M$34,P9)
A10: =COUNTIFS('06_RAID_LOG'!$C$5:$C$34,"Issue",'06_RAID_LOG'!$N$5:$N$34,"<>Closed") | C10: =COUNTIF('07_ACTION_TRACKER'!$K$5:$K$34,">0") | E10: =SUM('02_PROJECT_PORTFOLIO'!$O$5:$O$34) | G10: =SUM('02_PROJECT_PORTFOLIO'!$P$5:$P$34) | I10: =SUM('02_PROJECT_PORTFOLIO'!$Q$5:$Q$34) | K10: =COUNTIFS('05_MILESTONES'!$F$5:$F$34,">="&TODAY(),'05_MILESTONES'!$F$5:$F$34,"<="&TODAY()+7,'05_MILESTONES'!$H$5:$H$34,"<>Complete") | M10: =COUNTIF('17_DECISION_LOG'!$L$5:$L$34,"Pending")
A11: ="ESCALATED: "&COUNTIFS('06_RAID_LOG'!$C$5:$C$34,"Issue",'06_RAID_LOG'!$N$5:$N$34,"<>Closed",'06_RAID_LOG'!$O$5:$O$34,"Yes") | C11: ="WORST: "&MAX('07_ACTION_TRACKER'!$K$5:$K$34)&" DAYS LATE" | E11: TOTAL APPROVED | G11: =TEXT(IFERROR(G10/E10,0),"0%")&" OF APPROVED" | I11: =IF(I10>E10,"OVER APPROVED BY "&TEXT(I10-E10,"#,##0"),"WITHIN APPROVED") | K11: ="OVERDUE: "&COUNTIFS('05_MILESTONES'!$F$5:$F$34,">0",'05_MILESTONES'!$F$5:$F$34,"<"&TODAY(),'05_MILESTONES'!$H$5:$H$34,"<>Complete") | M11: ="CHANGES PENDING: "&COUNTIF('10_CHANGE_CONTROL'!$N$5:$N$34,"Pending") | P11: BLOCK 2 - PROJECT RAG
P12: RAG | Q12: Projects
A13: MANAGEMENT ATTENTION - WHAT NEEDS A DECISION THIS WEEK | P13: Green | Q13: =COUNTIF('02_PROJECT_PORTFOLIO'!$N$5:$N$34,P13)
A14: ="RED / DELAYED PROJECTS ("&COUNTIF('02_PROJECT_PORTFOLIO'!$N$5:$N$34,"Red")&")" | H14: ="TOP OPEN RISKS BY SCORE ("&COUNTIFS('06_RAID_LOG'!$C$5:$C$34,"Risk",'06_RAID_LOG'!$N$5:$N$34,"<>Closed")&")" | P14: Yellow | Q14: =COUNTIF('02_PROJECT_PORTFOLIO'!$N$5:$N$34,P14)
A15: ="•"&IFERROR(INDEX('02_PROJECT_PORTFOLIO'!$C$5:$C$34,MATCH(1,'02_PROJECT_PORTFOLIO'!$Z$5:$Z$34,0))&" ["&INDEX('02_PROJECT_PORTFOLIO'!$M$5:$M$34,MATCH(1,'02_PROJECT_PORTFOLIO'!$Z$5:$Z$34,0))&"] "&INDEX('02_PROJECT_PORTFOLIO'!$D$5:$D$34,MATCH(1,'02_PROJECT_PORTFOLIO'!$Z$5:$Z$34,0))&" - forecast "&TEXT(INDEX('02_PROJECT_PORTFOLIO'!$J$5:$J$34,MATCH(1,'02_PROJECT_PORTFOLIO'!$Z$5:$Z$34,0)),"dd-mmm-yy"),"") | H15: ="•"&IFERROR(INDEX('06_RAID_LOG'!$D$5:$D$34,MATCH(1,'06_RAID_LOG'!$S$5:$S$34,0))&" ("&INDEX('06_RAID_LOG'!$I$5:$I$34,MATCH(1,'06_RAID_LOG'!$S$5:$S$34,0))&" - "&INDEX('06_RAID_LOG'!$B$5:$B$34,MATCH(1,'06_RAID_LOG'!$S$5:$S$34,0))&")","") | P15: Red | Q15: =COUNTIF('02_PROJECT_PORTFOLIO'!$N$5:$N$34,P15)
A16: ="•"&IFERROR(INDEX('02_PROJECT_PORTFOLIO'!$C$5:$C$34,MATCH(2,'02_PROJECT_PORTFOLIO'!$Z$5:$Z$34,0))&" ["&INDEX('02_PROJECT_PORTFOLIO'!$M$5:$M$34,MATCH(2,'02_PROJECT_PORTFOLIO'!$Z$5:$Z$34,0))&"] "&INDEX('02_PROJECT_PORTFOLIO'!$D$5:$D$34,MATCH(2,'02_PROJECT_PORTFOLIO'!$Z$5:$Z$34,0))&" - forecast "&TEXT(INDEX('02_PROJECT_PORTFOLIO'!$J$5:$J$34,MATCH(2,'02_PROJECT_PORTFOLIO'!$Z$5:$Z$34,0)),"dd-mmm-yy"),"") | H16: ="•"&IFERROR(INDEX('06_RAID_LOG'!$D$5:$D$34,MATCH(2,'06_RAID_LOG'!$S$5:$S$34,0))&" ("&INDEX('06_RAID_LOG'!$I$5:$I$34,MATCH(2,'06_RAID_LOG'!$S$5:$S$34,0))&" - "&INDEX('06_RAID_LOG'!$B$5:$B$34,MATCH(2,'06_RAID_LOG'!$S$5:$S$34,0))&")","")
A17: ="•"&IFERROR(INDEX('02_PROJECT_PORTFOLIO'!$C$5:$C$34,MATCH(3,'02_PROJECT_PORTFOLIO'!$Z$5:$Z$34,0))&" ["&INDEX('02_PROJECT_PORTFOLIO'!$M$5:$M$34,MATCH(3,'02_PROJECT_PORTFOLIO'!$Z$5:$Z$34,0))&"] "&INDEX('02_PROJECT_PORTFOLIO'!$D$5:$D$34,MATCH(3,'02_PROJECT_PORTFOLIO'!$Z$5:$Z$34,0))&" - forecast "&TEXT(INDEX('02_PROJECT_PORTFOLIO'!$J$5:$J$34,MATCH(3,'02_PROJECT_PORTFOLIO'!$Z$5:$Z$34,0)),"dd-mmm-yy"),"") | H17: ="•"&IFERROR(INDEX('06_RAID_LOG'!$D$5:$D$34,MATCH(3,'06_RAID_LOG'!$S$5:$S$34,0))&" ("&INDEX('06_RAID_LOG'!$I$5:$I$34,MATCH(3,'06_RAID_LOG'!$S$5:$S$34,0))&" - "&INDEX('06_RAID_LOG'!$B$5:$B$34,MATCH(3,'06_RAID_LOG'!$S$5:$S$34,0))&")","") | P17: BLOCK 3 - PROJECT COMPLETION
A18: ="•"&IFERROR(INDEX('02_PROJECT_PORTFOLIO'!$C$5:$C$34,MATCH(4,'02_PROJECT_PORTFOLIO'!$Z$5:$Z$34,0))&" ["&INDEX('02_PROJECT_PORTFOLIO'!$M$5:$M$34,MATCH(4,'02_PROJECT_PORTFOLIO'!$Z$5:$Z$34,0))&"] "&INDEX('02_PROJECT_PORTFOLIO'!$D$5:$D$34,MATCH(4,'02_PROJECT_PORTFOLIO'!$Z$5:$Z$34,0))&" - forecast "&TEXT(INDEX('02_PROJECT_PORTFOLIO'!$J$5:$J$34,MATCH(4,'02_PROJECT_PORTFOLIO'!$Z$5:$Z$34,0)),"dd-mmm-yy"),"") | H18: ="•"&IFERROR(INDEX('06_RAID_LOG'!$D$5:$D$34,MATCH(4,'06_RAID_LOG'!$S$5:$S$34,0))&" ("&INDEX('06_RAID_LOG'!$I$5:$I$34,MATCH(4,'06_RAID_LOG'!$S$5:$S$34,0))&" - "&INDEX('06_RAID_LOG'!$B$5:$B$34,MATCH(4,'06_RAID_LOG'!$S$5:$S$34,0))&")","") | P18: Project | Q18: % Complete
A19: ="•"&IFERROR(INDEX('02_PROJECT_PORTFOLIO'!$C$5:$C$34,MATCH(5,'02_PROJECT_PORTFOLIO'!$Z$5:$Z$34,0))&" ["&INDEX('02_PROJECT_PORTFOLIO'!$M$5:$M$34,MATCH(5,'02_PROJECT_PORTFOLIO'!$Z$5:$Z$34,0))&"] "&INDEX('02_PROJECT_PORTFOLIO'!$D$5:$D$34,MATCH(5,'02_PROJECT_PORTFOLIO'!$Z$5:$Z$34,0))&" - forecast "&TEXT(INDEX('02_PROJECT_PORTFOLIO'!$J$5:$J$34,MATCH(5,'02_PROJECT_PORTFOLIO'!$Z$5:$Z$34,0)),"dd-mmm-yy"),"") | H19: ="•"&IFERROR(INDEX('06_RAID_LOG'!$D$5:$D$34,MATCH(5,'06_RAID_LOG'!$S$5:$S$34,0))&" ("&INDEX('06_RAID_LOG'!$I$5:$I$34,MATCH(5,'06_RAID_LOG'!$S$5:$S$34,0))&" - "&INDEX('06_RAID_LOG'!$B$5:$B$34,MATCH(5,'06_RAID_LOG'!$S$5:$S$34,0))&")","") | P19: =IFERROR(INDEX('02_PROJECT_PORTFOLIO'!$C$5:$C$34,MATCH(1,'02_PROJECT_PORTFOLIO'!$Y$5:$Y$34,0)),"") | Q19: =IF($P19="","",INDEX('02_PROJECT_PORTFOLIO'!$L$5:$L$34,MATCH($P19,'02_PROJECT_PORTFOLIO'!$C$5:$C$34,0)))
P20: =IFERROR(INDEX('02_PROJECT_PORTFOLIO'!$C$5:$C$34,MATCH(2,'02_PROJECT_PORTFOLIO'!$Y$5:$Y$34,0)),"") | Q20: =IF($P20="","",INDEX('02_PROJECT_PORTFOLIO'!$L$5:$L$34,MATCH($P20,'02_PROJECT_PORTFOLIO'!$C$5:$C$34,0)))
A21: ="OVERDUE ACTIONS ("&COUNTIF('07_ACTION_TRACKER'!$K$5:$K$34,">0")&")" | H21: ="PENDING APPROVALS & DECISIONS" | P21: =IFERROR(INDEX('02_PROJECT_PORTFOLIO'!$C$5:$C$34,MATCH(3,'02_PROJECT_PORTFOLIO'!$Y$5:$Y$34,0)),"") | Q21: =IF($P21="","",INDEX('02_PROJECT_PORTFOLIO'!$L$5:$L$34,MATCH($P21,'02_PROJECT_PORTFOLIO'!$C$5:$C$34,0)))
A22: ="•"&IFERROR(INDEX('07_ACTION_TRACKER'!$E$5:$E$34,MATCH(1,'07_ACTION_TRACKER'!$O$5:$O$34,0))&": "&LEFT(INDEX('07_ACTION_TRACKER'!$D$5:$D$34,MATCH(1,'07_ACTION_TRACKER'!$O$5:$O$34,0)),42)&" ("&INDEX('07_ACTION_TRACKER'!$K$5:$K$34,MATCH(1,'07_ACTION_TRACKER'!$O$5:$O$34,0))&"d late)","") | H22: ="•"&IFERROR(INDEX('10_CHANGE_CONTROL'!$A$5:$A$34,MATCH(1,'10_CHANGE_CONTROL'!$T$5:$T$34,0))&" "&LEFT(INDEX('10_CHANGE_CONTROL'!$E$5:$E$34,MATCH(1,'10_CHANGE_CONTROL'!$T$5:$T$34,0)),44)&" ["&TEXT(INDEX('10_CHANGE_CONTROL'!$I$5:$I$34,MATCH(1,'10_CHANGE_CONTROL'!$T$5:$T$34,0)),"#,##0")&"]","") | P22: =IFERROR(INDEX('02_PROJECT_PORTFOLIO'!$C$5:$C$34,MATCH(4,'02_PROJECT_PORTFOLIO'!$Y$5:$Y$34,0)),"") | Q22: =IF($P22="","",INDEX('02_PROJECT_PORTFOLIO'!$L$5:$L$34,MATCH($P22,'02_PROJECT_PORTFOLIO'!$C$5:$C$34,0)))
A23: ="•"&IFERROR(INDEX('07_ACTION_TRACKER'!$E$5:$E$34,MATCH(2,'07_ACTION_TRACKER'!$O$5:$O$34,0))&": "&LEFT(INDEX('07_ACTION_TRACKER'!$D$5:$D$34,MATCH(2,'07_ACTION_TRACKER'!$O$5:$O$34,0)),42)&" ("&INDEX('07_ACTION_TRACKER'!$K$5:$K$34,MATCH(2,'07_ACTION_TRACKER'!$O$5:$O$34,0))&"d late)","") | H23: ="•"&IFERROR(INDEX('10_CHANGE_CONTROL'!$A$5:$A$34,MATCH(2,'10_CHANGE_CONTROL'!$T$5:$T$34,0))&" "&LEFT(INDEX('10_CHANGE_CONTROL'!$E$5:$E$34,MATCH(2,'10_CHANGE_CONTROL'!$T$5:$T$34,0)),44)&" ["&TEXT(INDEX('10_CHANGE_CONTROL'!$I$5:$I$34,MATCH(2,'10_CHANGE_CONTROL'!$T$5:$T$34,0)),"#,##0")&"]","") | P23: =IFERROR(INDEX('02_PROJECT_PORTFOLIO'!$C$5:$C$34,MATCH(5,'02_PROJECT_PORTFOLIO'!$Y$5:$Y$34,0)),"") | Q23: =IF($P23="","",INDEX('02_PROJECT_PORTFOLIO'!$L$5:$L$34,MATCH($P23,'02_PROJECT_PORTFOLIO'!$C$5:$C$34,0)))
A24: ="•"&IFERROR(INDEX('07_ACTION_TRACKER'!$E$5:$E$34,MATCH(3,'07_ACTION_TRACKER'!$O$5:$O$34,0))&": "&LEFT(INDEX('07_ACTION_TRACKER'!$D$5:$D$34,MATCH(3,'07_ACTION_TRACKER'!$O$5:$O$34,0)),42)&" ("&INDEX('07_ACTION_TRACKER'!$K$5:$K$34,MATCH(3,'07_ACTION_TRACKER'!$O$5:$O$34,0))&"d late)","") | H24: ="•"&IFERROR(INDEX('10_CHANGE_CONTROL'!$A$5:$A$34,MATCH(3,'10_CHANGE_CONTROL'!$T$5:$T$34,0))&" "&LEFT(INDEX('10_CHANGE_CONTROL'!$E$5:$E$34,MATCH(3,'10_CHANGE_CONTROL'!$T$5:$T$34,0)),44)&" ["&TEXT(INDEX('10_CHANGE_CONTROL'!$I$5:$I$34,MATCH(3,'10_CHANGE_CONTROL'!$T$5:$T$34,0)),"#,##0")&"]","") | P24: =IFERROR(INDEX('02_PROJECT_PORTFOLIO'!$C$5:$C$34,MATCH(6,'02_PROJECT_PORTFOLIO'!$Y$5:$Y$34,0)),"") | Q24: =IF($P24="","",INDEX('02_PROJECT_PORTFOLIO'!$L$5:$L$34,MATCH($P24,'02_PROJECT_PORTFOLIO'!$C$5:$C$34,0)))
A25: ="•"&IFERROR(INDEX('07_ACTION_TRACKER'!$E$5:$E$34,MATCH(4,'07_ACTION_TRACKER'!$O$5:$O$34,0))&": "&LEFT(INDEX('07_ACTION_TRACKER'!$D$5:$D$34,MATCH(4,'07_ACTION_TRACKER'!$O$5:$O$34,0)),42)&" ("&INDEX('07_ACTION_TRACKER'!$K$5:$K$34,MATCH(4,'07_ACTION_TRACKER'!$O$5:$O$34,0))&"d late)","") | H25: ="•"&"Decisions pending: "&COUNTIF('17_DECISION_LOG'!$L$5:$L$34,"Pending")&" | decisions overdue: "&COUNTIFS('17_DECISION_LOG'!$L$5:$L$34,"Pending",'17_DECISION_LOG'!$K$5:$K$34,"<"&TODAY())&" | milestones overdue: "&COUNTIFS('05_MILESTONES'!$F$5:$F$34,">0",'05_MILESTONES'!$F$5:$F$34,"<"&TODAY(),'05_MILESTONES'!$H$5:$H$34,"<>Complete") | P25: =IFERROR(INDEX('02_PROJECT_PORTFOLIO'!$C$5:$C$34,MATCH(7,'02_PROJECT_PORTFOLIO'!$Y$5:$Y$34,0)),"") | Q25: =IF($P25="","",INDEX('02_PROJECT_PORTFOLIO'!$L$5:$L$34,MATCH($P25,'02_PROJECT_PORTFOLIO'!$C$5:$C$34,0)))
A26: ="•"&IFERROR(INDEX('07_ACTION_TRACKER'!$E$5:$E$34,MATCH(5,'07_ACTION_TRACKER'!$O$5:$O$34,0))&": "&LEFT(INDEX('07_ACTION_TRACKER'!$D$5:$D$34,MATCH(5,'07_ACTION_TRACKER'!$O$5:$O$34,0)),42)&" ("&INDEX('07_ACTION_TRACKER'!$K$5:$K$34,MATCH(5,'07_ACTION_TRACKER'!$O$5:$O$34,0))&"d late)","") | H26: ="•"&"Pending change value: "&TEXT(SUMIFS('10_CHANGE_CONTROL'!$I$5:$I$34,'10_CHANGE_CONTROL'!$N$5:$N$34,"Pending"),"#,##0")&" | quality failures: "&COUNTIF('14_QUALITY_CONTROL'!$H$5:$H$34,"Fail")&" | closure items open: "&COUNTIFS('19_PROJECT_CLOSURE'!$F$5:$F$34,"<>Complete",'19_PROJECT_CLOSURE'!$F$5:$F$34,"<>N/A",'19_PROJECT_CLOSURE'!$A$5:$A$34,"?*") | P26: =IFERROR(INDEX('02_PROJECT_PORTFOLIO'!$C$5:$C$34,MATCH(8,'02_PROJECT_PORTFOLIO'!$Y$5:$Y$34,0)),"") | Q26: =IF($P26="","",INDEX('02_PROJECT_PORTFOLIO'!$L$5:$L$34,MATCH($P26,'02_PROJECT_PORTFOLIO'!$C$5:$C$34,0)))
P27: =IFERROR(INDEX('02_PROJECT_PORTFOLIO'!$C$5:$C$34,MATCH(9,'02_PROJECT_PORTFOLIO'!$Y$5:$Y$34,0)),"") | Q27: =IF($P27="","",INDEX('02_PROJECT_PORTFOLIO'!$L$5:$L$34,MATCH($P27,'02_PROJECT_PORTFOLIO'!$C$5:$C$34,0)))
A28: NEXT 10 MILESTONES - AUTOMATIC, CLOSEST FORECAST DATE FIRST | P28: =IFERROR(INDEX('02_PROJECT_PORTFOLIO'!$C$5:$C$34,MATCH(10,'02_PROJECT_PORTFOLIO'!$Y$5:$Y$34,0)),"") | Q28: =IF($P28="","",INDEX('02_PROJECT_PORTFOLIO'!$L$5:$L$34,MATCH($P28,'02_PROJECT_PORTFOLIO'!$C$5:$C$34,0)))
A29: MILESTONE | E29: PROJECT | H29: OWNER | J29: FORECAST DATE | L29: DAYS | N29: RAG
A30: =IFERROR(INDEX('05_MILESTONES'!$C$5:$C$34,MATCH(SMALL('05_MILESTONES'!$M$5:$M$34,1),'05_MILESTONES'!$M$5:$M$34,0)),"") | E30: =IFERROR(INDEX('05_MILESTONES'!$B$5:$B$34,MATCH(SMALL('05_MILESTONES'!$M$5:$M$34,1),'05_MILESTONES'!$M$5:$M$34,0)),"") | H30: =IFERROR(INDEX('05_MILESTONES'!$D$5:$D$34,MATCH(SMALL('05_MILESTONES'!$M$5:$M$34,1),'05_MILESTONES'!$M$5:$M$34,0)),"") | J30: =IFERROR(INDEX('05_MILESTONES'!$F$5:$F$34,MATCH(SMALL('05_MILESTONES'!$M$5:$M$34,1),'05_MILESTONES'!$M$5:$M$34,0)),"") | L30: =IFERROR(INDEX('05_MILESTONES'!$I$5:$I$34,MATCH(SMALL('05_MILESTONES'!$M$5:$M$34,1),'05_MILESTONES'!$M$5:$M$34,0)),"") | N30: =IFERROR(INDEX('05_MILESTONES'!$K$5:$K$34,MATCH(SMALL('05_MILESTONES'!$M$5:$M$34,1),'05_MILESTONES'!$M$5:$M$34,0)),"") | P30: BLOCK 4 - PLANNED vs ACTUAL PROGRESS
A31: =IFERROR(INDEX('05_MILESTONES'!$C$5:$C$34,MATCH(SMALL('05_MILESTONES'!$M$5:$M$34,2),'05_MILESTONES'!$M$5:$M$34,0)),"") | E31: =IFERROR(INDEX('05_MILESTONES'!$B$5:$B$34,MATCH(SMALL('05_MILESTONES'!$M$5:$M$34,2),'05_MILESTONES'!$M$5:$M$34,0)),"") | H31: =IFERROR(INDEX('05_MILESTONES'!$D$5:$D$34,MATCH(SMALL('05_MILESTONES'!$M$5:$M$34,2),'05_MILESTONES'!$M$5:$M$34,0)),"") | J31: =IFERROR(INDEX('05_MILESTONES'!$F$5:$F$34,MATCH(SMALL('05_MILESTONES'!$M$5:$M$34,2),'05_MILESTONES'!$M$5:$M$34,0)),"") | L31: =IFERROR(INDEX('05_MILESTONES'!$I$5:$I$34,MATCH(SMALL('05_MILESTONES'!$M$5:$M$34,2),'05_MILESTONES'!$M$5:$M$34,0)),"") | N31: =IFERROR(INDEX('05_MILESTONES'!$K$5:$K$34,MATCH(SMALL('05_MILESTONES'!$M$5:$M$34,2),'05_MILESTONES'!$M$5:$M$34,0)),"") | P31: Project | Q31: Planned to date | R31: Actual
A32: =IFERROR(INDEX('05_MILESTONES'!$C$5:$C$34,MATCH(SMALL('05_MILESTONES'!$M$5:$M$34,3),'05_MILESTONES'!$M$5:$M$34,0)),"") | E32: =IFERROR(INDEX('05_MILESTONES'!$B$5:$B$34,MATCH(SMALL('05_MILESTONES'!$M$5:$M$34,3),'05_MILESTONES'!$M$5:$M$34,0)),"") | H32: =IFERROR(INDEX('05_MILESTONES'!$D$5:$D$34,MATCH(SMALL('05_MILESTONES'!$M$5:$M$34,3),'05_MILESTONES'!$M$5:$M$34,0)),"") | J32: =IFERROR(INDEX('05_MILESTONES'!$F$5:$F$34,MATCH(SMALL('05_MILESTONES'!$M$5:$M$34,3),'05_MILESTONES'!$M$5:$M$34,0)),"") | L32: =IFERROR(INDEX('05_MILESTONES'!$I$5:$I$34,MATCH(SMALL('05_MILESTONES'!$M$5:$M$34,3),'05_MILESTONES'!$M$5:$M$34,0)),"") | N32: =IFERROR(INDEX('05_MILESTONES'!$K$5:$K$34,MATCH(SMALL('05_MILESTONES'!$M$5:$M$34,3),'05_MILESTONES'!$M$5:$M$34,0)),"") | P32: =IFERROR(INDEX('02_PROJECT_PORTFOLIO'!$C$5:$C$34,MATCH(1,'02_PROJECT_PORTFOLIO'!$Y$5:$Y$34,0)),"") | Q32: =IF($P32="","",IFERROR(MAX(0,MIN(1,(TODAY()-INDEX('02_PROJECT_PORTFOLIO'!$H$5:$H$34,MATCH($P32,'02_PROJECT_PORTFOLIO'!$C$5:$C$34,0)))/(INDEX('02_PROJECT_PORTFOLIO'!$I$5:$I$34,MATCH($P32,'02_PROJECT_PORTFOLIO'!$C$5:$C$34,0))-INDEX('02_PROJECT_PORTFOLIO'!$H$5:$H$34,MATCH($P32,'02_PROJECT_PORTFOLIO'!$C$5:$C$34,0))))),"")) | R32: =IF($P32="","",INDEX('02_PROJECT_PORTFOLIO'!$L$5:$L$34,MATCH($P32,'02_PROJECT_PORTFOLIO'!$C$5:$C$34,0)))
A33: =IFERROR(INDEX('05_MILESTONES'!$C$5:$C$34,MATCH(SMALL('05_MILESTONES'!$M$5:$M$34,4),'05_MILESTONES'!$M$5:$M$34,0)),"") | E33: =IFERROR(INDEX('05_MILESTONES'!$B$5:$B$34,MATCH(SMALL('05_MILESTONES'!$M$5:$M$34,4),'05_MILESTONES'!$M$5:$M$34,0)),"") | H33: =IFERROR(INDEX('05_MILESTONES'!$D$5:$D$34,MATCH(SMALL('05_MILESTONES'!$M$5:$M$34,4),'05_MILESTONES'!$M$5:$M$34,0)),"") | J33: =IFERROR(INDEX('05_MILESTONES'!$F$5:$F$34,MATCH(SMALL('05_MILESTONES'!$M$5:$M$34,4),'05_MILESTONES'!$M$5:$M$34,0)),"") | L33: =IFERROR(INDEX('05_MILESTONES'!$I$5:$I$34,MATCH(SMALL('05_MILESTONES'!$M$5:$M$34,4),'05_MILESTONES'!$M$5:$M$34,0)),"") | N33: =IFERROR(INDEX('05_MILESTONES'!$K$5:$K$34,MATCH(SMALL('05_MILESTONES'!$M$5:$M$34,4),'05_MILESTONES'!$M$5:$M$34,0)),"") | P33: =IFERROR(INDEX('02_PROJECT_PORTFOLIO'!$C$5:$C$34,MATCH(2,'02_PROJECT_PORTFOLIO'!$Y$5:$Y$34,0)),"") | Q33: =IF($P33="","",IFERROR(MAX(0,MIN(1,(TODAY()-INDEX('02_PROJECT_PORTFOLIO'!$H$5:$H$34,MATCH($P33,'02_PROJECT_PORTFOLIO'!$C$5:$C$34,0)))/(INDEX('02_PROJECT_PORTFOLIO'!$I$5:$I$34,MATCH($P33,'02_PROJECT_PORTFOLIO'!$C$5:$C$34,0))-INDEX('02_PROJECT_PORTFOLIO'!$H$5:$H$34,MATCH($P33,'02_PROJECT_PORTFOLIO'!$C$5:$C$34,0))))),"")) | R33: =IF($P33="","",INDEX('02_PROJECT_PORTFOLIO'!$L$5:$L$34,MATCH($P33,'02_PROJECT_PORTFOLIO'!$C$5:$C$34,0)))
A34: =IFERROR(INDEX('05_MILESTONES'!$C$5:$C$34,MATCH(SMALL('05_MILESTONES'!$M$5:$M$34,5),'05_MILESTONES'!$M$5:$M$34,0)),"") | E34: =IFERROR(INDEX('05_MILESTONES'!$B$5:$B$34,MATCH(SMALL('05_MILESTONES'!$M$5:$M$34,5),'05_MILESTONES'!$M$5:$M$34,0)),"") | H34: =IFERROR(INDEX('05_MILESTONES'!$D$5:$D$34,MATCH(SMALL('05_MILESTONES'!$M$5:$M$34,5),'05_MILESTONES'!$M$5:$M$34,0)),"") | J34: =IFERROR(INDEX('05_MILESTONES'!$F$5:$F$34,MATCH(SMALL('05_MILESTONES'!$M$5:$M$34,5),'05_MILESTONES'!$M$5:$M$34,0)),"") | L34: =IFERROR(INDEX('05_MILESTONES'!$I$5:$I$34,MATCH(SMALL('05_MILESTONES'!$M$5:$M$34,5),'05_MILESTONES'!$M$5:$M$34,0)),"") | N34: =IFERROR(INDEX('05_MILESTONES'!$K$5:$K$34,MATCH(SMALL('05_MILESTONES'!$M$5:$M$34,5),'05_MILESTONES'!$M$5:$M$34,0)),"") | P34: =IFERROR(INDEX('02_PROJECT_PORTFOLIO'!$C$5:$C$34,MATCH(3,'02_PROJECT_PORTFOLIO'!$Y$5:$Y$34,0)),"") | Q34: =IF($P34="","",IFERROR(MAX(0,MIN(1,(TODAY()-INDEX('02_PROJECT_PORTFOLIO'!$H$5:$H$34,MATCH($P34,'02_PROJECT_PORTFOLIO'!$C$5:$C$34,0)))/(INDEX('02_PROJECT_PORTFOLIO'!$I$5:$I$34,MATCH($P34,'02_PROJECT_PORTFOLIO'!$C$5:$C$34,0))-INDEX('02_PROJECT_PORTFOLIO'!$H$5:$H$34,MATCH($P34,'02_PROJECT_PORTFOLIO'!$C$5:$C$34,0))))),"")) | R34: =IF($P34="","",INDEX('02_PROJECT_PORTFOLIO'!$L$5:$L$34,MATCH($P34,'02_PROJECT_PORTFOLIO'!$C$5:$C$34,0)))
A35: =IFERROR(INDEX('05_MILESTONES'!$C$5:$C$34,MATCH(SMALL('05_MILESTONES'!$M$5:$M$34,6),'05_MILESTONES'!$M$5:$M$34,0)),"") | E35: =IFERROR(INDEX('05_MILESTONES'!$B$5:$B$34,MATCH(SMALL('05_MILESTONES'!$M$5:$M$34,6),'05_MILESTONES'!$M$5:$M$34,0)),"") | H35: =IFERROR(INDEX('05_MILESTONES'!$D$5:$D$34,MATCH(SMALL('05_MILESTONES'!$M$5:$M$34,6),'05_MILESTONES'!$M$5:$M$34,0)),"") | J35: =IFERROR(INDEX('05_MILESTONES'!$F$5:$F$34,MATCH(SMALL('05_MILESTONES'!$M$5:$M$34,6),'05_MILESTONES'!$M$5:$M$34,0)),"") | L35: =IFERROR(INDEX('05_MILESTONES'!$I$5:$I$34,MATCH(SMALL('05_MILESTONES'!$M$5:$M$34,6),'05_MILESTONES'!$M$5:$M$34,0)),"") | N35: =IFERROR(INDEX('05_MILESTONES'!$K$5:$K$34,MATCH(SMALL('05_MILESTONES'!$M$5:$M$34,6),'05_MILESTONES'!$M$5:$M$34,0)),"") | P35: =IFERROR(INDEX('02_PROJECT_PORTFOLIO'!$C$5:$C$34,MATCH(4,'02_PROJECT_PORTFOLIO'!$Y$5:$Y$34,0)),"") | Q35: =IF($P35="","",IFERROR(MAX(0,MIN(1,(TODAY()-INDEX('02_PROJECT_PORTFOLIO'!$H$5:$H$34,MATCH($P35,'02_PROJECT_PORTFOLIO'!$C$5:$C$34,0)))/(INDEX('02_PROJECT_PORTFOLIO'!$I$5:$I$34,MATCH($P35,'02_PROJECT_PORTFOLIO'!$C$5:$C$34,0))-INDEX('02_PROJECT_PORTFOLIO'!$H$5:$H$34,MATCH($P35,'02_PROJECT_PORTFOLIO'!$C$5:$C$34,0))))),"")) | R35: =IF($P35="","",INDEX('02_PROJECT_PORTFOLIO'!$L$5:$L$34,MATCH($P35,'02_PROJECT_PORTFOLIO'!$C$5:$C$34,0)))
A36: =IFERROR(INDEX('05_MILESTONES'!$C$5:$C$34,MATCH(SMALL('05_MILESTONES'!$M$5:$M$34,7),'05_MILESTONES'!$M$5:$M$34,0)),"") | E36: =IFERROR(INDEX('05_MILESTONES'!$B$5:$B$34,MATCH(SMALL('05_MILESTONES'!$M$5:$M$34,7),'05_MILESTONES'!$M$5:$M$34,0)),"") | H36: =IFERROR(INDEX('05_MILESTONES'!$D$5:$D$34,MATCH(SMALL('05_MILESTONES'!$M$5:$M$34,7),'05_MILESTONES'!$M$5:$M$34,0)),"") | J36: =IFERROR(INDEX('05_MILESTONES'!$F$5:$F$34,MATCH(SMALL('05_MILESTONES'!$M$5:$M$34,7),'05_MILESTONES'!$M$5:$M$34,0)),"") | L36: =IFERROR(INDEX('05_MILESTONES'!$I$5:$I$34,MATCH(SMALL('05_MILESTONES'!$M$5:$M$34,7),'05_MILESTONES'!$M$5:$M$34,0)),"") | N36: =IFERROR(INDEX('05_MILESTONES'!$K$5:$K$34,MATCH(SMALL('05_MILESTONES'!$M$5:$M$34,7),'05_MILESTONES'!$M$5:$M$34,0)),"") | P36: =IFERROR(INDEX('02_PROJECT_PORTFOLIO'!$C$5:$C$34,MATCH(5,'02_PROJECT_PORTFOLIO'!$Y$5:$Y$34,0)),"") | Q36: =IF($P36="","",IFERROR(MAX(0,MIN(1,(TODAY()-INDEX('02_PROJECT_PORTFOLIO'!$H$5:$H$34,MATCH($P36,'02_PROJECT_PORTFOLIO'!$C$5:$C$34,0)))/(INDEX('02_PROJECT_PORTFOLIO'!$I$5:$I$34,MATCH($P36,'02_PROJECT_PORTFOLIO'!$C$5:$C$34,0))-INDEX('02_PROJECT_PORTFOLIO'!$H$5:$H$34,MATCH($P36,'02_PROJECT_PORTFOLIO'!$C$5:$C$34,0))))),"")) | R36: =IF($P36="","",INDEX('02_PROJECT_PORTFOLIO'!$L$5:$L$34,MATCH($P36,'02_PROJECT_PORTFOLIO'!$C$5:$C$34,0)))
A37: =IFERROR(INDEX('05_MILESTONES'!$C$5:$C$34,MATCH(SMALL('05_MILESTONES'!$M$5:$M$34,8),'05_MILESTONES'!$M$5:$M$34,0)),"") | E37: =IFERROR(INDEX('05_MILESTONES'!$B$5:$B$34,MATCH(SMALL('05_MILESTONES'!$M$5:$M$34,8),'05_MILESTONES'!$M$5:$M$34,0)),"") | H37: =IFERROR(INDEX('05_MILESTONES'!$D$5:$D$34,MATCH(SMALL('05_MILESTONES'!$M$5:$M$34,8),'05_MILESTONES'!$M$5:$M$34,0)),"") | J37: =IFERROR(INDEX('05_MILESTONES'!$F$5:$F$34,MATCH(SMALL('05_MILESTONES'!$M$5:$M$34,8),'05_MILESTONES'!$M$5:$M$34,0)),"") | L37: =IFERROR(INDEX('05_MILESTONES'!$I$5:$I$34,MATCH(SMALL('05_MILESTONES'!$M$5:$M$34,8),'05_MILESTONES'!$M$5:$M$34,0)),"") | N37: =IFERROR(INDEX('05_MILESTONES'!$K$5:$K$34,MATCH(SMALL('05_MILESTONES'!$M$5:$M$34,8),'05_MILESTONES'!$M$5:$M$34,0)),"") | P37: =IFERROR(INDEX('02_PROJECT_PORTFOLIO'!$C$5:$C$34,MATCH(6,'02_PROJECT_PORTFOLIO'!$Y$5:$Y$34,0)),"") | Q37: =IF($P37="","",IFERROR(MAX(0,MIN(1,(TODAY()-INDEX('02_PROJECT_PORTFOLIO'!$H$5:$H$34,MATCH($P37,'02_PROJECT_PORTFOLIO'!$C$5:$C$34,0)))/(INDEX('02_PROJECT_PORTFOLIO'!$I$5:$I$34,MATCH($P37,'02_PROJECT_PORTFOLIO'!$C$5:$C$34,0))-INDEX('02_PROJECT_PORTFOLIO'!$H$5:$H$34,MATCH($P37,'02_PROJECT_PORTFOLIO'!$C$5:$C$34,0))))),"")) | R37: =IF($P37="","",INDEX('02_PROJECT_PORTFOLIO'!$L$5:$L$34,MATCH($P37,'02_PROJECT_PORTFOLIO'!$C$5:$C$34,0)))
A38: =IFERROR(INDEX('05_MILESTONES'!$C$5:$C$34,MATCH(SMALL('05_MILESTONES'!$M$5:$M$34,9),'05_MILESTONES'!$M$5:$M$34,0)),"") | E38: =IFERROR(INDEX('05_MILESTONES'!$B$5:$B$34,MATCH(SMALL('05_MILESTONES'!$M$5:$M$34,9),'05_MILESTONES'!$M$5:$M$34,0)),"") | H38: =IFERROR(INDEX('05_MILESTONES'!$D$5:$D$34,MATCH(SMALL('05_MILESTONES'!$M$5:$M$34,9),'05_MILESTONES'!$M$5:$M$34,0)),"") | J38: =IFERROR(INDEX('05_MILESTONES'!$F$5:$F$34,MATCH(SMALL('05_MILESTONES'!$M$5:$M$34,9),'05_MILESTONES'!$M$5:$M$34,0)),"") | L38: =IFERROR(INDEX('05_MILESTONES'!$I$5:$I$34,MATCH(SMALL('05_MILESTONES'!$M$5:$M$34,9),'05_MILESTONES'!$M$5:$M$34,0)),"") | N38: =IFERROR(INDEX('05_MILESTONES'!$K$5:$K$34,MATCH(SMALL('05_MILESTONES'!$M$5:$M$34,9),'05_MILESTONES'!$M$5:$M$34,0)),"") | P38: =IFERROR(INDEX('02_PROJECT_PORTFOLIO'!$C$5:$C$34,MATCH(7,'02_PROJECT_PORTFOLIO'!$Y$5:$Y$34,0)),"") | Q38: =IF($P38="","",IFERROR(MAX(0,MIN(1,(TODAY()-INDEX('02_PROJECT_PORTFOLIO'!$H$5:$H$34,MATCH($P38,'02_PROJECT_PORTFOLIO'!$C$5:$C$34,0)))/(INDEX('02_PROJECT_PORTFOLIO'!$I$5:$I$34,MATCH($P38,'02_PROJECT_PORTFOLIO'!$C$5:$C$34,0))-INDEX('02_PROJECT_PORTFOLIO'!$H$5:$H$34,MATCH($P38,'02_PROJECT_PORTFOLIO'!$C$5:$C$34,0))))),"")) | R38: =IF($P38="","",INDEX('02_PROJECT_PORTFOLIO'!$L$5:$L$34,MATCH($P38,'02_PROJECT_PORTFOLIO'!$C$5:$C$34,0)))
A39: =IFERROR(INDEX('05_MILESTONES'!$C$5:$C$34,MATCH(SMALL('05_MILESTONES'!$M$5:$M$34,10),'05_MILESTONES'!$M$5:$M$34,0)),"") | E39: =IFERROR(INDEX('05_MILESTONES'!$B$5:$B$34,MATCH(SMALL('05_MILESTONES'!$M$5:$M$34,10),'05_MILESTONES'!$M$5:$M$34,0)),"") | H39: =IFERROR(INDEX('05_MILESTONES'!$D$5:$D$34,MATCH(SMALL('05_MILESTONES'!$M$5:$M$34,10),'05_MILESTONES'!$M$5:$M$34,0)),"") | J39: =IFERROR(INDEX('05_MILESTONES'!$F$5:$F$34,MATCH(SMALL('05_MILESTONES'!$M$5:$M$34,10),'05_MILESTONES'!$M$5:$M$34,0)),"") | L39: =IFERROR(INDEX('05_MILESTONES'!$I$5:$I$34,MATCH(SMALL('05_MILESTONES'!$M$5:$M$34,10),'05_MILESTONES'!$M$5:$M$34,0)),"") | N39: =IFERROR(INDEX('05_MILESTONES'!$K$5:$K$34,MATCH(SMALL('05_MILESTONES'!$M$5:$M$34,10),'05_MILESTONES'!$M$5:$M$34,0)),"") | P39: =IFERROR(INDEX('02_PROJECT_PORTFOLIO'!$C$5:$C$34,MATCH(8,'02_PROJECT_PORTFOLIO'!$Y$5:$Y$34,0)),"") | Q39: =IF($P39="","",IFERROR(MAX(0,MIN(1,(TODAY()-INDEX('02_PROJECT_PORTFOLIO'!$H$5:$H$34,MATCH($P39,'02_PROJECT_PORTFOLIO'!$C$5:$C$34,0)))/(INDEX('02_PROJECT_PORTFOLIO'!$I$5:$I$34,MATCH($P39,'02_PROJECT_PORTFOLIO'!$C$5:$C$34,0))-INDEX('02_PROJECT_PORTFOLIO'!$H$5:$H$34,MATCH($P39,'02_PROJECT_PORTFOLIO'!$C$5:$C$34,0))))),"")) | R39: =IF($P39="","",INDEX('02_PROJECT_PORTFOLIO'!$L$5:$L$34,MATCH($P39,'02_PROJECT_PORTFOLIO'!$C$5:$C$34,0)))
P40: =IFERROR(INDEX('02_PROJECT_PORTFOLIO'!$C$5:$C$34,MATCH(9,'02_PROJECT_PORTFOLIO'!$Y$5:$Y$34,0)),"") | Q40: =IF($P40="","",IFERROR(MAX(0,MIN(1,(TODAY()-INDEX('02_PROJECT_PORTFOLIO'!$H$5:$H$34,MATCH($P40,'02_PROJECT_PORTFOLIO'!$C$5:$C$34,0)))/(INDEX('02_PROJECT_PORTFOLIO'!$I$5:$I$34,MATCH($P40,'02_PROJECT_PORTFOLIO'!$C$5:$C$34,0))-INDEX('02_PROJECT_PORTFOLIO'!$H$5:$H$34,MATCH($P40,'02_PROJECT_PORTFOLIO'!$C$5:$C$34,0))))),"")) | R40: =IF($P40="","",INDEX('02_PROJECT_PORTFOLIO'!$L$5:$L$34,MATCH($P40,'02_PROJECT_PORTFOLIO'!$C$5:$C$34,0)))
...

Sheet 01B_PROJECT_DASHBOARD
A1: PROJECT DASHBOARD | P1: AUTOMATIC CHART DATA - FORMULAS ONLY, DO NOT EDIT
A2: ="SINGLE PROJECT VIEW - "&IF($D$3="","SELECT A PROJECT IN ROW 3",$D$3)
A3: SELECT PROJECT: | D3: ERP Implementation | I3: ="AS AT "&TEXT(TODAY(),"dd mmm yyyy")&" | LAST UPDATED: "&IFERROR(TEXT(INDEX('02_PROJECT_PORTFOLIO'!$W$5:$W$34,MATCH($D$3,'02_PROJECT_PORTFOLIO'!$C$5:$C$34,0)),"dd mmm yyyy"),"-") | P3: BLOCK 1 - TASK STATUS
A4: PROJECT SNAPSHOT - EVERY FIGURE FOLLOWS THE PROJECT SELECTED ABOVE | P4: Status | Q4: Tasks
A5: STATUS | C5: RAG | E5: % COMPLETE | G5: SCHEDULE VARIANCE | I5: APPROVED AMOUNT | K5: ACTUAL COST | M5: FORECAST COST | P5: Not Started | Q5: =COUNTIFS('04_WBS_SCHEDULE'!$B$5:$B$34,$D$3,'04_WBS_SCHEDULE'!$N$5:$N$34,P5)
A6: =IFERROR(INDEX('02_PROJECT_PORTFOLIO'!$M$5:$M$34,MATCH($D$3,'02_PROJECT_PORTFOLIO'!$C$5:$C$34,0)),"-") | C6: =IFERROR(INDEX('02_PROJECT_PORTFOLIO'!$N$5:$N$34,MATCH($D$3,'02_PROJECT_PORTFOLIO'!$C$5:$C$34,0)),"-") | E6: =IFERROR(INDEX('02_PROJECT_PORTFOLIO'!$L$5:$L$34,MATCH($D$3,'02_PROJECT_PORTFOLIO'!$C$5:$C$34,0)),"-") | G6: =IFERROR(INDEX('02_PROJECT_PORTFOLIO'!$R$5:$R$34,MATCH($D$3,'02_PROJECT_PORTFOLIO'!$C$5:$C$34,0)),"-") | I6: =IFERROR(INDEX('02_PROJECT_PORTFOLIO'!$O$5:$O$34,MATCH($D$3,'02_PROJECT_PORTFOLIO'!$C$5:$C$34,0)),"-") | K6: =IFERROR(INDEX('02_PROJECT_PORTFOLIO'!$P$5:$P$34,MATCH($D$3,'02_PROJECT_PORTFOLIO'!$C$5:$C$34,0)),"-") | M6: =IFERROR(INDEX('02_PROJECT_PORTFOLIO'!$Q$5:$Q$34,MATCH($D$3,'02_PROJECT_PORTFOLIO'!$C$5:$C$34,0)),"-") | P6: In Progress | Q6: =COUNTIFS('04_WBS_SCHEDULE'!$B$5:$B$34,$D$3,'04_WBS_SCHEDULE'!$N$5:$N$34,P6)
A7: LIFECYCLE STATUS | C7: OVERALL HEALTH | E7: REPORTED BY THE PM | G7: FORECAST vs BASELINE (DAYS) | I7: TOTAL APPROVED | K7: SPENT TO DATE | M7: EXPECTED AT COMPLETION | P7: Complete | Q7: =COUNTIFS('04_WBS_SCHEDULE'!$B$5:$B$34,$D$3,'04_WBS_SCHEDULE'!$N$5:$N$34,P7)
P8: Blocked | Q8: =COUNTIFS('04_WBS_SCHEDULE'!$B$5:$B$34,$D$3,'04_WBS_SCHEDULE'!$N$5:$N$34,P8)
A9: PROJECT HEALTH | C9: CUSTOMER | E9: PROJECT MANAGER | G9: DEPARTMENT | I9: PRIORITY | K9: START DATE | M9: BASELINE END
A10: =IFERROR(INDEX('02_PROJECT_PORTFOLIO'!$V$5:$V$34,MATCH($D$3,'02_PROJECT_PORTFOLIO'!$C$5:$C$34,0)),"-") | C10: =IFERROR(INDEX('02_PROJECT_PORTFOLIO'!$B$5:$B$34,MATCH($D$3,'02_PROJECT_PORTFOLIO'!$C$5:$C$34,0)),"-") | E10: =IFERROR(INDEX('02_PROJECT_PORTFOLIO'!$D$5:$D$34,MATCH($D$3,'02_PROJECT_PORTFOLIO'!$C$5:$C$34,0)),"-") | G10: =IFERROR(INDEX('02_PROJECT_PORTFOLIO'!$E$5:$E$34,MATCH($D$3,'02_PROJECT_PORTFOLIO'!$C$5:$C$34,0)),"-") | I10: =IFERROR(INDEX('02_PROJECT_PORTFOLIO'!$G$5:$G$34,MATCH($D$3,'02_PROJECT_PORTFOLIO'!$C$5:$C$34,0)),"-") | K10: =IFERROR(INDEX('02_PROJECT_PORTFOLIO'!$H$5:$H$34,MATCH($D$3,'02_PROJECT_PORTFOLIO'!$C$5:$C$34,0)),"-") | M10: =IFERROR(INDEX('02_PROJECT_PORTFOLIO'!$I$5:$I$34,MATCH($D$3,'02_PROJECT_PORTFOLIO'!$C$5:$C$34,0)),"-") | P10: BLOCK 2 - TASKS BY OWNER
A11: AUTOMATIC FLAG | C11: CLIENT / INTERNAL | E11: ACCOUNTABLE OWNER | G11: OWNING DEPARTMENT | I11: BUSINESS PRIORITY | K11: PLANNED START | M11: CONTRACTUAL FINISH | P11: Owner | Q11: Tasks
P12: Ahmed Khan | Q12: =COUNTIFS('04_WBS_SCHEDULE'!$B$5:$B$34,$D$3,'04_WBS_SCHEDULE'!$F$5:$F$34,P12)
A13: PROJECT DETAIL (AUTOMATIC) | P13: Lisa Chen | Q13: =COUNTIFS('04_WBS_SCHEDULE'!$B$5:$B$34,$D$3,'04_WBS_SCHEDULE'!$F$5:$F$34,P13)
A14: SCHEDULE VARIANCE (DAYS) | C14: =IFERROR(INDEX('02_PROJECT_PORTFOLIO'!$R$5:$R$34,MATCH($D$3,'02_PROJECT_PORTFOLIO'!$C$5:$C$34,0)),"-") | F14: FORECAST vs APPROVED | H14: =IFERROR(INDEX('02_PROJECT_PORTFOLIO'!$O$5:$O$34,MATCH($D$3,'02_PROJECT_PORTFOLIO'!$C$5:$C$34,0))-INDEX('02_PROJECT_PORTFOLIO'!$Q$5:$Q$34,MATCH($D$3,'02_PROJECT_PORTFOLIO'!$C$5:$C$34,0)),"-") | K14: COST UTILISATION | M14: =IFERROR(INDEX('02_PROJECT_PORTFOLIO'!$P$5:$P$34,MATCH($D$3,'02_PROJECT_PORTFOLIO'!$C$5:$C$34,0))/INDEX('02_PROJECT_PORTFOLIO'!$O$5:$O$34,MATCH($D$3,'02_PROJECT_PORTFOLIO'!$C$5:$C$34,0)),"-") | P14: David Okoro | Q14: =COUNTIFS('04_WBS_SCHEDULE'!$B$5:$B$34,$D$3,'04_WBS_SCHEDULE'!$F$5:$F$34,P14)
A15: BASELINE END | C15: =IFERROR(INDEX('02_PROJECT_PORTFOLIO'!$I$5:$I$34,MATCH($D$3,'02_PROJECT_PORTFOLIO'!$C$5:$C$34,0)),"-") | F15: FORECAST END | H15: =IFERROR(INDEX('02_PROJECT_PORTFOLIO'!$J$5:$J$34,MATCH($D$3,'02_PROJECT_PORTFOLIO'!$C$5:$C$34,0)),"-") | K15: ACTUAL END | M15: =IFERROR(INDEX('02_PROJECT_PORTFOLIO'!$K$5:$K$34,MATCH($D$3,'02_PROJECT_PORTFOLIO'!$C$5:$C$34,0)),"-") | P15: Maria Silva | Q15: =COUNTIFS('04_WBS_SCHEDULE'!$B$5:$B$34,$D$3,'04_WBS_SCHEDULE'!$F$5:$F$34,P15)
A16: OPEN RISKS | C16: =COUNTIFS('06_RAID_LOG'!$B$5:$B$34,$D$3,'06_RAID_LOG'!$C$5:$C$34,"Risk",'06_RAID_LOG'!$N$5:$N$34,"<>Closed") | F16: OPEN ISSUES | H16: =COUNTIFS('06_RAID_LOG'!$B$5:$B$34,$D$3,'06_RAID_LOG'!$C$5:$C$34,"Issue",'06_RAID_LOG'!$N$5:$N$34,"<>Closed") | K16: OVERDUE ACTIONS | M16: =COUNTIFS('07_ACTION_TRACKER'!$B$5:$B$34,$D$3,'07_ACTION_TRACKER'!$K$5:$K$34,">0") | P16: Priya Raman | Q16: =COUNTIFS('04_WBS_SCHEDULE'!$B$5:$B$34,$D$3,'04_WBS_SCHEDULE'!$F$5:$F$34,P16)
A17: NEXT MILESTONE | C17: =IFERROR(INDEX('05_MILESTONES'!$C$5:$C$34,MATCH($D$3&"|1",'05_MILESTONES'!$N$5:$N$34,0)),"-") | F17: MILESTONE DATE | H17: =IFERROR(INDEX('05_MILESTONES'!$F$5:$F$34,MATCH($D$3&"|1",'05_MILESTONES'!$N$5:$N$34,0)),"-") | K17: TASKS COMPLETE | M17: =IF(COUNTIF('04_WBS_SCHEDULE'!$B$5:$B$34,$D$3)=0,"-",COUNTIFS('04_WBS_SCHEDULE'!$B$5:$B$34,$D$3,'04_WBS_SCHEDULE'!$N$5:$N$34,"Complete")&" of "&COUNTIF('04_WBS_SCHEDULE'!$B$5:$B$34,$D$3)) | P17: Tom Becker | Q17: =COUNTIFS('04_WBS_SCHEDULE'!$B$5:$B$34,$D$3,'04_WBS_SCHEDULE'!$F$5:$F$34,P17)
P18: Grace Alemu | Q18: =COUNTIFS('04_WBS_SCHEDULE'!$B$5:$B$34,$D$3,'04_WBS_SCHEDULE'!$F$5:$F$34,P18)
A19: ="TOP OPEN RISKS ("&COUNTIFS('06_RAID_LOG'!$B$5:$B$34,$D$3,'06_RAID_LOG'!$C$5:$C$34,"Risk",'06_RAID_LOG'!$N$5:$N$34,"<>Closed")&")" | H19: ="TOP ISSUES ("&COUNTIFS('06_RAID_LOG'!$B$5:$B$34,$D$3,'06_RAID_LOG'!$C$5:$C$34,"Issue",'06_RAID_LOG'!$N$5:$N$34,"<>Closed")&")" | P19: Sarah Mitchell | Q19: =COUNTIFS('04_WBS_SCHEDULE'!$B$5:$B$34,$D$3,'04_WBS_SCHEDULE'!$F$5:$F$34,P19)
A20: ="•"&IFERROR(INDEX('06_RAID_LOG'!$D$5:$D$34,MATCH("Risk|"&$D$3&"|1",'06_RAID_LOG'!$T$5:$T$34,0))&" ("&INDEX('06_RAID_LOG'!$I$5:$I$34,MATCH("Risk|"&$D$3&"|1",'06_RAID_LOG'!$T$5:$T$34,0))&" - "&INDEX('06_RAID_LOG'!$J$5:$J$34,MATCH("Risk|"&$D$3&"|1",'06_RAID_LOG'!$T$5:$T$34,0))&")","") | H20: ="•"&IFERROR(INDEX('06_RAID_LOG'!$D$5:$D$34,MATCH("Issue|"&$D$3&"|1",'06_RAID_LOG'!$T$5:$T$34,0))&" ("&INDEX('06_RAID_LOG'!$I$5:$I$34,MATCH("Issue|"&$D$3&"|1",'06_RAID_LOG'!$T$5:$T$34,0))&" - "&INDEX('06_RAID_LOG'!$J$5:$J$34,MATCH("Issue|"&$D$3&"|1",'06_RAID_LOG'!$T$5:$T$34,0))&")","")
A21: ="•"&IFERROR(INDEX('06_RAID_LOG'!$D$5:$D$34,MATCH("Risk|"&$D$3&"|2",'06_RAID_LOG'!$T$5:$T$34,0))&" ("&INDEX('06_RAID_LOG'!$I$5:$I$34,MATCH("Risk|"&$D$3&"|2",'06_RAID_LOG'!$T$5:$T$34,0))&" - "&INDEX('06_RAID_LOG'!$J$5:$J$34,MATCH("Risk|"&$D$3&"|2",'06_RAID_LOG'!$T$5:$T$34,0))&")","") | H21: ="•"&IFERROR(INDEX('06_RAID_LOG'!$D$5:$D$34,MATCH("Issue|"&$D$3&"|2",'06_RAID_LOG'!$T$5:$T$34,0))&" ("&INDEX('06_RAID_LOG'!$I$5:$I$34,MATCH("Issue|"&$D$3&"|2",'06_RAID_LOG'!$T$5:$T$34,0))&" - "&INDEX('06_RAID_LOG'!$J$5:$J$34,MATCH("Issue|"&$D$3&"|2",'06_RAID_LOG'!$T$5:$T$34,0))&")","") | P21: BLOCK 3 - OPEN RAID BY TYPE
A22: ="•"&IFERROR(INDEX('06_RAID_LOG'!$D$5:$D$34,MATCH("Risk|"&$D$3&"|3",'06_RAID_LOG'!$T$5:$T$34,0))&" ("&INDEX('06_RAID_LOG'!$I$5:$I$34,MATCH("Risk|"&$D$3&"|3",'06_RAID_LOG'!$T$5:$T$34,0))&" - "&INDEX('06_RAID_LOG'!$J$5:$J$34,MATCH("Risk|"&$D$3&"|3",'06_RAID_LOG'!$T$5:$T$34,0))&")","") | H22: ="•"&IFERROR(INDEX('06_RAID_LOG'!$D$5:$D$34,MATCH("Issue|"&$D$3&"|3",'06_RAID_LOG'!$T$5:$T$34,0))&" ("&INDEX('06_RAID_LOG'!$I$5:$I$34,MATCH("Issue|"&$D$3&"|3",'06_RAID_LOG'!$T$5:$T$34,0))&" - "&INDEX('06_RAID_LOG'!$J$5:$J$34,MATCH("Issue|"&$D$3&"|3",'06_RAID_LOG'!$T$5:$T$34,0))&")","") | P22: Type | Q22: Open items
A23: ="•"&IFERROR(INDEX('06_RAID_LOG'!$D$5:$D$34,MATCH("Risk|"&$D$3&"|4",'06_RAID_LOG'!$T$5:$T$34,0))&" ("&INDEX('06_RAID_LOG'!$I$5:$I$34,MATCH("Risk|"&$D$3&"|4",'06_RAID_LOG'!$T$5:$T$34,0))&" - "&INDEX('06_RAID_LOG'!$J$5:$J$34,MATCH("Risk|"&$D$3&"|4",'06_RAID_LOG'!$T$5:$T$34,0))&")","") | H23: ="•"&IFERROR(INDEX('06_RAID_LOG'!$D$5:$D$34,MATCH("Issue|"&$D$3&"|4",'06_RAID_LOG'!$T$5:$T$34,0))&" ("&INDEX('06_RAID_LOG'!$I$5:$I$34,MATCH("Issue|"&$D$3&"|4",'06_RAID_LOG'!$T$5:$T$34,0))&" - "&INDEX('06_RAID_LOG'!$J$5:$J$34,MATCH("Issue|"&$D$3&"|4",'06_RAID_LOG'!$T$5:$T$34,0))&")","") | P23: Risk | Q23: =COUNTIFS('06_RAID_LOG'!$B$5:$B$34,$D$3,'06_RAID_LOG'!$C$5:$C$34,P23,'06_RAID_LOG'!$N$5:$N$34,"<>Closed")
A24: ="•"&IFERROR(INDEX('06_RAID_LOG'!$D$5:$D$34,MATCH("Risk|"&$D$3&"|5",'06_RAID_LOG'!$T$5:$T$34,0))&" ("&INDEX('06_RAID_LOG'!$I$5:$I$34,MATCH("Risk|"&$D$3&"|5",'06_RAID_LOG'!$T$5:$T$34,0))&" - "&INDEX('06_RAID_LOG'!$J$5:$J$34,MATCH("Risk|"&$D$3&"|5",'06_RAID_LOG'!$T$5:$T$34,0))&")","") | H24: ="•"&IFERROR(INDEX('06_RAID_LOG'!$D$5:$D$34,MATCH("Issue|"&$D$3&"|5",'06_RAID_LOG'!$T$5:$T$34,0))&" ("&INDEX('06_RAID_LOG'!$I$5:$I$34,MATCH("Issue|"&$D$3&"|5",'06_RAID_LOG'!$T$5:$T$34,0))&" - "&INDEX('06_RAID_LOG'!$J$5:$J$34,MATCH("Issue|"&$D$3&"|5",'06_RAID_LOG'!$T$5:$T$34,0))&")","") | P24: Assumption | Q24: =COUNTIFS('06_RAID_LOG'!$B$5:$B$34,$D$3,'06_RAID_LOG'!$C$5:$C$34,P24,'06_RAID_LOG'!$N$5:$N$34,"<>Closed")
P25: Issue | Q25: =COUNTIFS('06_RAID_LOG'!$B$5:$B$34,$D$3,'06_RAID_LOG'!$C$5:$C$34,P25,'06_RAID_LOG'!$N$5:$N$34,"<>Closed")
A26: ="OPEN ACTIONS ("&COUNTIFS('07_ACTION_TRACKER'!$B$5:$B$34,$D$3,'07_ACTION_TRACKER'!$I$5:$I$34,"<>Complete")&")" | H26: ="UPCOMING MILESTONES ("&COUNTIFS('05_MILESTONES'!$B$5:$B$34,$D$3,'05_MILESTONES'!$H$5:$H$34,"<>Complete")&")" | P26: Dependency | Q26: =COUNTIFS('06_RAID_LOG'!$B$5:$B$34,$D$3,'06_RAID_LOG'!$C$5:$C$34,P26,'06_RAID_LOG'!$N$5:$N$34,"<>Closed")
A27: ="•"&IFERROR(INDEX('07_ACTION_TRACKER'!$E$5:$E$34,MATCH($D$3&"|1",'07_ACTION_TRACKER'!$P$5:$P$34,0))&": "&LEFT(INDEX('07_ACTION_TRACKER'!$D$5:$D$34,MATCH($D$3&"|1",'07_ACTION_TRACKER'!$P$5:$P$34,0)),40)&" due "&TEXT(INDEX('07_ACTION_TRACKER'!$H$5:$H$34,MATCH($D$3&"|1",'07_ACTION_TRACKER'!$P$5:$P$34,0)),"dd-mmm"),"") | H27: ="•"&IFERROR(INDEX('05_MILESTONES'!$C$5:$C$34,MATCH($D$3&"|1",'05_MILESTONES'!$N$5:$N$34,0))&" ("&TEXT(INDEX('05_MILESTONES'!$F$5:$F$34,MATCH($D$3&"|1",'05_MILESTONES'!$N$5:$N$34,0)),"dd-mmm-yy")&", "&INDEX('05_MILESTONES'!$D$5:$D$34,MATCH($D$3&"|1",'05_MILESTONES'!$N$5:$N$34,0))&")","")
A28: ="•"&IFERROR(INDEX('07_ACTION_TRACKER'!$E$5:$E$34,MATCH($D$3&"|2",'07_ACTION_TRACKER'!$P$5:$P$34,0))&": "&LEFT(INDEX('07_ACTION_TRACKER'!$D$5:$D$34,MATCH($D$3&"|2",'07_ACTION_TRACKER'!$P$5:$P$34,0)),40)&" due "&TEXT(INDEX('07_ACTION_TRACKER'!$H$5:$H$34,MATCH($D$3&"|2",'07_ACTION_TRACKER'!$P$5:$P$34,0)),"dd-mmm"),"") | H28: ="•"&IFERROR(INDEX('05_MILESTONES'!$C$5:$C$34,MATCH($D$3&"|2",'05_MILESTONES'!$N$5:$N$34,0))&" ("&TEXT(INDEX('05_MILESTONES'!$F$5:$F$34,MATCH($D$3&"|2",'05_MILESTONES'!$N$5:$N$34,0)),"dd-mmm-yy")&", "&INDEX('05_MILESTONES'!$D$5:$D$34,MATCH($D$3&"|2",'05_MILESTONES'!$N$5:$N$34,0))&")","") | P28: BLOCK 4 - COST BY CATEGORY
A29: ="•"&IFERROR(INDEX('07_ACTION_TRACKER'!$E$5:$E$34,MATCH($D$3&"|3",'07_ACTION_TRACKER'!$P$5:$P$34,0))&": "&LEFT(INDEX('07_ACTION_TRACKER'!$D$5:$D$34,MATCH($D$3&"|3",'07_ACTION_TRACKER'!$P$5:$P$34,0)),40)&" due "&TEXT(INDEX('07_ACTION_TRACKER'!$H$5:$H$34,MATCH($D$3&"|3",'07_ACTION_TRACKER'!$P$5:$P$34,0)),"dd-mmm"),"") | H29: ="•"&IFERROR(INDEX('05_MILESTONES'!$C$5:$C$34,MATCH($D$3&"|3",'05_MILESTONES'!$N$5:$N$34,0))&" ("&TEXT(INDEX('05_MILESTONES'!$F$5:$F$34,MATCH($D$3&"|3",'05_MILESTONES'!$N$5:$N$34,0)),"dd-mmm-yy")&", "&INDEX('05_MILESTONES'!$D$5:$D$34,MATCH($D$3&"|3",'05_MILESTONES'!$N$5:$N$34,0))&")","") | P29: Category | Q29: Approved | R29: Actual | S29: Forecast
A30: ="•"&IFERROR(INDEX('07_ACTION_TRACKER'!$E$5:$E$34,MATCH($D$3&"|4",'07_ACTION_TRACKER'!$P$5:$P$34,0))&": "&LEFT(INDEX('07_ACTION_TRACKER'!$D$5:$D$34,MATCH($D$3&"|4",'07_ACTION_TRACKER'!$P$5:$P$34,0)),40)&" due "&TEXT(INDEX('07_ACTION_TRACKER'!$H$5:$H$34,MATCH($D$3&"|4",'07_ACTION_TRACKER'!$P$5:$P$34,0)),"dd-mmm"),"") | H30: ="•"&IFERROR(INDEX('05_MILESTONES'!$C$5:$C$34,MATCH($D$3&"|4",'05_MILESTONES'!$N$5:$N$34,0))&" ("&TEXT(INDEX('05_MILESTONES'!$F$5:$F$34,MATCH($D$3&"|4",'05_MILESTONES'!$N$5:$N$34,0)),"dd-mmm-yy")&", "&INDEX('05_MILESTONES'!$D$5:$D$34,MATCH($D$3&"|4",'05_MILESTONES'!$N$5:$N$34,0))&")","") | P30: Personnel | Q30: =SUMIFS('11_COST_MANAGEMENT'!$E$5:$E$34,'11_COST_MANAGEMENT'!$B$5:$B$34,$D$3,'11_COST_MANAGEMENT'!$C$5:$C$34,$P30) | R30: =SUMIFS('11_COST_MANAGEMENT'!$G$5:$G$34,'11_COST_MANAGEMENT'!$B$5:$B$34,$D$3,'11_COST_MANAGEMENT'!$C$5:$C$34,$P30) | S30: =SUMIFS('11_COST_MANAGEMENT'!$H$5:$H$34,'11_COST_MANAGEMENT'!$B$5:$B$34,$D$3,'11_COST_MANAGEMENT'!$C$5:$C$34,$P30)
A31: ="•"&IFERROR(INDEX('07_ACTION_TRACKER'!$E$5:$E$34,MATCH($D$3&"|5",'07_ACTION_TRACKER'!$P$5:$P$34,0))&": "&LEFT(INDEX('07_ACTION_TRACKER'!$D$5:$D$34,MATCH($D$3&"|5",'07_ACTION_TRACKER'!$P$5:$P$34,0)),40)&" due "&TEXT(INDEX('07_ACTION_TRACKER'!$H$5:$H$34,MATCH($D$3&"|5",'07_ACTION_TRACKER'!$P$5:$P$34,0)),"dd-mmm"),"") | H31: ="•"&IFERROR(INDEX('05_MILESTONES'!$C$5:$C$34,MATCH($D$3&"|5",'05_MILESTONES'!$N$5:$N$34,0))&" ("&TEXT(INDEX('05_MILESTONES'!$F$5:$F$34,MATCH($D$3&"|5",'05_MILESTONES'!$N$5:$N$34,0)),"dd-mmm-yy")&", "&INDEX('05_MILESTONES'!$D$5:$D$34,MATCH($D$3&"|5",'05_MILESTONES'!$N$5:$N$34,0))&")","") | P31: Software | Q31: =SUMIFS('11_COST_MANAGEMENT'!$E$5:$E$34,'11_COST_MANAGEMENT'!$B$5:$B$34,$D$3,'11_COST_MANAGEMENT'!$C$5:$C$34,$P31) | R31: =SUMIFS('11_COST_MANAGEMENT'!$G$5:$G$34,'11_COST_MANAGEMENT'!$B$5:$B$34,$D$3,'11_COST_MANAGEMENT'!$C$5:$C$34,$P31) | S31: =SUMIFS('11_COST_MANAGEMENT'!$H$5:$H$34,'11_COST_MANAGEMENT'!$B$5:$B$34,$D$3,'11_COST_MANAGEMENT'!$C$5:$C$34,$P31)
P32: Hardware | Q32: =SUMIFS('11_COST_MANAGEMENT'!$E$5:$E$34,'11_COST_MANAGEMENT'!$B$5:$B$34,$D$3,'11_COST_MANAGEMENT'!$C$5:$C$34,$P32) | R32: =SUMIFS('11_COST_MANAGEMENT'!$G$5:$G$34,'11_COST_MANAGEMENT'!$B$5:$B$34,$D$3,'11_COST_MANAGEMENT'!$C$5:$C$34,$P32) | S32: =SUMIFS('11_COST_MANAGEMENT'!$H$5:$H$34,'11_COST_MANAGEMENT'!$B$5:$B$34,$D$3,'11_COST_MANAGEMENT'!$C$5:$C$34,$P32)
A33: PROJECT CHARTS - RECALCULATE WHEN YOU CHANGE THE PROJECT SELECTED ABOVE | P33: Procurement | Q33: =SUMIFS('11_COST_MANAGEMENT'!$E$5:$E$34,'11_COST_MANAGEMENT'!$B$5:$B$34,$D$3,'11_COST_MANAGEMENT'!$C$5:$C$34,$P33) | R33: =SUMIFS('11_COST_MANAGEMENT'!$G$5:$G$34,'11_COST_MANAGEMENT'!$B$5:$B$34,$D$3,'11_COST_MANAGEMENT'!$C$5:$C$34,$P33) | S33: =SUMIFS('11_COST_MANAGEMENT'!$H$5:$H$34,'11_COST_MANAGEMENT'!$B$5:$B$34,$D$3,'11_COST_MANAGEMENT'!$C$5:$C$34,$P33)
P34: Consulting | Q34: =SUMIFS('11_COST_MANAGEMENT'!$E$5:$E$34,'11_COST_MANAGEMENT'!$B$5:$B$34,$D$3,'11_COST_MANAGEMENT'!$C$5:$C$34,$P34) | R34: =SUMIFS('11_COST_MANAGEMENT'!$G$5:$G$34,'11_COST_MANAGEMENT'!$B$5:$B$34,$D$3,'11_COST_MANAGEMENT'!$C$5:$C$34,$P34) | S34: =SUMIFS('11_COST_MANAGEMENT'!$H$5:$H$34,'11_COST_MANAGEMENT'!$B$5:$B$34,$D$3,'11_COST_MANAGEMENT'!$C$5:$C$34,$P34)
P35: Training | Q35: =SUMIFS('11_COST_MANAGEMENT'!$E$5:$E$34,'11_COST_MANAGEMENT'!$B$5:$B$34,$D$3,'11_COST_MANAGEMENT'!$C$5:$C$34,$P35) | R35: =SUMIFS('11_COST_MANAGEMENT'!$G$5:$G$34,'11_COST_MANAGEMENT'!$B$5:$B$34,$D$3,'11_COST_MANAGEMENT'!$C$5:$C$34,$P35) | S35: =SUMIFS('11_COST_MANAGEMENT'!$H$5:$H$34,'11_COST_MANAGEMENT'!$B$5:$B$34,$D$3,'11_COST_MANAGEMENT'!$C$5:$C$34,$P35)
P36: Travel | Q36: =SUMIFS('11_COST_MANAGEMENT'!$E$5:$E$34,'11_COST_MANAGEMENT'!$B$5:$B$34,$D$3,'11_COST_MANAGEMENT'!$C$5:$C$34,$P36) | R36: =SUMIFS('11_COST_MANAGEMENT'!$G$5:$G$34,'11_COST_MANAGEMENT'!$B$5:$B$34,$D$3,'11_COST_MANAGEMENT'!$C$5:$C$34,$P36) | S36: =SUMIFS('11_COST_MANAGEMENT'!$H$5:$H$34,'11_COST_MANAGEMENT'!$B$5:$B$34,$D$3,'11_COST_MANAGEMENT'!$C$5:$C$34,$P36)
P37: Other | Q37: =SUMIFS('11_COST_MANAGEMENT'!$E$5:$E$34,'11_COST_MANAGEMENT'!$B$5:$B$34,$D$3,'11_COST_MANAGEMENT'!$C$5:$C$34,$P37) | R37: =SUMIFS('11_COST_MANAGEMENT'!$G$5:$G$34,'11_COST_MANAGEMENT'!$B$5:$B$34,$D$3,'11_COST_MANAGEMENT'!$C$5:$C$34,$P37) | S37: =SUMIFS('11_COST_MANAGEMENT'!$H$5:$H$34,'11_COST_MANAGEMENT'!$B$5:$B$34,$D$3,'11_COST_MANAGEMENT'!$C$5:$C$34,$P37)
P39: BLOCK 5 - MILESTONE STATUS
P40: Status | Q40: Milestones
P41: Not Started | Q41: =COUNTIFS('05_MILESTONES'!$B$5:$B$34,$D$3,'05_MILESTONES'!$H$5:$H$34,P41)
...

Sheet 02_PROJECT_PORTFOLIO
A1: PROJECT PORTFOLIO REGISTER
A2: Single source of truth for every project: customer, schedule, RAG, approved amount, actual and forecast cost. Dashboard KPIs and charts read from this table.
A3: SAMPLE DATA - every sample record is marked SAMPLE in the Notes column. Delete or overwrite them freely: all formulas, KPIs, charts and drop-downs keep working.
A4: Project ID | B4: Customer | C4: Project Name | D4: Project Manager | E4: Department | F4: Project Type | G4: Priority | H4: Start Date | I4: Baseline End Date | J4: Forecast End Date | K4: Actual End Date | L4: % Complete | M4: Status | N4: RAG | O4: Total Approved Amount | P4: Actual Cost | Q4: Forecast Cost | R4: Schedule Variance | S4: Cost Variance | T4: Next Milestone | U4: Milestone Date | V4: Project Health | W4: Last Updated | X4: Notes | Y4: ChartIdx | Z4: RedRank | AA4: ViewRank | AB4: Timeline | AC4: Budget/Actual
A5: PRJ-001 | B5: HEINEKEN | C5: ERP Implementation | D5: Ahmed Khan | E5: IT | F5: System Implementation | G5: Critical | H5: 46204 | I5: 46374 | J5: 46402 | L5: 0.62 | M5: Active | N5: Yellow | O5: 850000 | P5: 520000 | Q5: 910000 | R5: =IF(OR(I5="",J5=""),"",J5-I5) | S5: =IF(OR(O5="",P5=""),"",O5-P5) | T5: =IFERROR(INDEX('05_MILESTONES'!$C$5:$C$34,MATCH(AGGREGATE(15,6,'05_MILESTONES'!$M$5:$M$34/('05_MILESTONES'!$B$5:$B$34=$C5),1),'05_MILESTONES'!$M$5:$M$34,0)),"") | U5: =IFERROR(INT(AGGREGATE(15,6,'05_MILESTONES'!$M$5:$M$34/('05_MILESTONES'!$B$5:$B$34=$C5),1)),"") | V5: =IF(C5="","",IF(M5="Completed","Closed",IF(M5="Cancelled","N/A",IF(N5="Red","Critical",IF(OR(N5="Yellow",AND(Q5<>"",O5<>"",Q5>O5),AND(R5<>"",R5>7)),"Needs Attention","Healthy"))))) | W5: 46302 | X5: SAMPLE - ERP rollout, one month late on baseline. | Y5: =IF(C5="","",COUNTIF($C$5:$C5,"?*")) | Z5: =IF(OR(C5="",N5<>"Red"),"",COUNTIF($N$5:$N$34,"Red")-COUNTIF($N$5:$N5,"Red")+1) | AA5: =IF(C5="","",IF(AND(OR('01_EXECUTIVE_DASHBOARD'!$C$42="All",'01_EXECUTIVE_DASHBOARD'!$C$42=$M5),OR('01_EXECUTIVE_DASHBOARD'!$F$42="All",'01_EXECUTIVE_DASHBOARD'!$F$42=$N5),OR('01_EXECUTIVE_DASHBOARD'!$I$42="All",'01_EXECUTIVE_DASHBOARD'!$I$42=$D5)),SUMPRODUCT(($C$5:$C5<>"")*((('01_EXECUTIVE_DASHBOARD'!$C$42="All")+($M$5:$M5='01_EXECUTIVE_DASHBOARD'!$C$42))>0)*((('01_EXECUTIVE_DASHBOARD'!$F$42="All")+($N$5:$N5='01_EXECUTIVE_DASHBOARD'!$F$42))>0)*((('01_EXECUTIVE_DASHBOARD'!$I$42="All")+($D$5:$D5='01_EXECUTIVE_DASHBOARD'!$I$42))>0)),"")) | AB5: =IF(C5="","",TEXT(H5,"dd-mmm-yy")&" - "&TEXT(IF(K5<>"",K5,J5),"dd-mmm-yy")) | AC5: =IF(C5="","",TEXT(O5,"#,##0")&" / "&TEXT(P5,"#,##0"))
A6: PRJ-002 | B6: Internal | C6: Network Infrastructure Upgrade | D6: Lisa Chen | E6: IT | F6: Infrastructure | G6: High | H6: 46249 | I6: 46356 | J6: 46351 | L6: 0.45 | M6: Active | N6: Green | O6: 320000 | P6: 140000 | Q6: 305000 | R6: =IF(OR(I6="",J6=""),"",J6-I6) | S6: =IF(OR(O6="",P6=""),"",O6-P6) | T6: =IFERROR(INDEX('05_MILESTONES'!$C$5:$C$34,MATCH(AGGREGATE(15,6,'05_MILESTONES'!$M$5:$M$34/('05_MILESTONES'!$B$5:$B$34=$C6),1),'05_MILESTONES'!$M$5:$M$34,0)),"") | U6: =IFERROR(INT(AGGREGATE(15,6,'05_MILESTONES'!$M$5:$M$34/('05_MILESTONES'!$B$5:$B$34=$C6),1)),"") | V6: =IF(C6="","",IF(M6="Completed","Closed",IF(M6="Cancelled","N/A",IF(N6="Red","Critical",IF(OR(N6="Yellow",AND(Q6<>"",O6<>"",Q6>O6),AND(R6<>"",R6>7)),"Needs Attention","Healthy"))))) | W6: 46302 | X6: SAMPLE - ahead of plan, vendor on track. | Y6: =IF(C6="","",COUNTIF($C$5:$C6,"?*")) | Z6: =IF(OR(C6="",N6<>"Red"),"",COUNTIF($N$5:$N$34,"Red")-COUNTIF($N$5:$N6,"Red")+1) | AA6: =IF(C6="","",IF(AND(OR('01_EXECUTIVE_DASHBOARD'!$C$42="All",'01_EXECUTIVE_DASHBOARD'!$C$42=$M6),OR('01_EXECUTIVE_DASHBOARD'!$F$42="All",'01_EXECUTIVE_DASHBOARD'!$F$42=$N6),OR('01_EXECUTIVE_DASHBOARD'!$I$42="All",'01_EXECUTIVE_DASHBOARD'!$I$42=$D6)),SUMPRODUCT(($C$5:$C6<>"")*((('01_EXECUTIVE_DASHBOARD'!$C$42="All")+($M$5:$M6='01_EXECUTIVE_DASHBOARD'!$C$42))>0)*((('01_EXECUTIVE_DASHBOARD'!$F$42="All")+($N$5:$N6='01_EXECUTIVE_DASHBOARD'!$F$42))>0)*((('01_EXECUTIVE_DASHBOARD'!$I$42="All")+($D$5:$D6='01_EXECUTIVE_DASHBOARD'!$I$42))>0)),"")) | AB6: =IF(C6="","",TEXT(H6,"dd-mmm-yy")&" - "&TEXT(IF(K6<>"",K6,J6),"dd-mmm-yy")) | AC6: =IF(C6="","",TEXT(O6,"#,##0")&" / "&TEXT(P6,"#,##0"))
A7: PRJ-003 | B7: H A K F TRADING PLC | C7: HR Management System | D7: David Okoro | E7: HR | F7: System Implementation | G7: High | H7: 46266 | I7: 46477 | J7: 46522 | L7: 0.22 | M7: Active | N7: Red | O7: 480000 | P7: 150000 | Q7: 560000 | R7: =IF(OR(I7="",J7=""),"",J7-I7) | S7: =IF(OR(O7="",P7=""),"",O7-P7) | T7: =IFERROR(INDEX('05_MILESTONES'!$C$5:$C$34,MATCH(AGGREGATE(15,6,'05_MILESTONES'!$M$5:$M$34/('05_MILESTONES'!$B$5:$B$34=$C7),1),'05_MILESTONES'!$M$5:$M$34,0)),"") | U7: =IFERROR(INT(AGGREGATE(15,6,'05_MILESTONES'!$M$5:$M$34/('05_MILESTONES'!$B$5:$B$34=$C7),1)),"") | V7: =IF(C7="","",IF(M7="Completed","Closed",IF(M7="Cancelled","N/A",IF(N7="Red","Critical",IF(OR(N7="Yellow",AND(Q7<>"",O7<>"",Q7>O7),AND(R7<>"",R7>7)),"Needs Attention","Healthy"))))) | W7: 46301 | X7: SAMPLE - vendor delay and forecast overrun. | Y7: =IF(C7="","",COUNTIF($C$5:$C7,"?*")) | Z7: =IF(OR(C7="",N7<>"Red"),"",COUNTIF($N$5:$N$34,"Red")-COUNTIF($N$5:$N7,"Red")+1) | AA7: =IF(C7="","",IF(AND(OR('01_EXECUTIVE_DASHBOARD'!$C$42="All",'01_EXECUTIVE_DASHBOARD'!$C$42=$M7),OR('01_EXECUTIVE_DASHBOARD'!$F$42="All",'01_EXECUTIVE_DASHBOARD'!$F$42=$N7),OR('01_EXECUTIVE_DASHBOARD'!$I$42="All",'01_EXECUTIVE_DASHBOARD'!$I$42=$D7)),SUMPRODUCT(($C$5:$C7<>"")*((('01_EXECUTIVE_DASHBOARD'!$C$42="All")+($M$5:$M7='01_EXECUTIVE_DASHBOARD'!$C$42))>0)*((('01_EXECUTIVE_DASHBOARD'!$F$42="All")+($N$5:$N7='01_EXECUTIVE_DASHBOARD'!$F$42))>0)*((('01_EXECUTIVE_DASHBOARD'!$I$42="All")+($D$5:$D7='01_EXECUTIVE_DASHBOARD'!$I$42))>0)),"")) | AB7: =IF(C7="","",TEXT(H7,"dd-mmm-yy")&" - "&TEXT(IF(K7<>"",K7,J7),"dd-mmm-yy")) | AC7: =IF(C7="","",TEXT(O7,"#,##0")&" / "&TEXT(P7,"#,##0"))
A8: PRJ-004 | B8: MEGERSA MERGA MEGENTA | C8: Website Development | D8: Maria Silva | E8: Marketing | F8: Development | G8: Medium | H8: 46280 | I8: 46341 | J8: 46361 | L8: 0.4 | M8: On Hold | N8: Yellow | O8: 120000 | P8: 62000 | Q8: 138000 | R8: =IF(OR(I8="",J8=""),"",J8-I8) | S8: =IF(OR(O8="",P8=""),"",O8-P8) | T8: =IFERROR(INDEX('05_MILESTONES'!$C$5:$C$34,MATCH(AGGREGATE(15,6,'05_MILESTONES'!$M$5:$M$34/('05_MILESTONES'!$B$5:$B$34=$C8),1),'05_MILESTONES'!$M$5:$M$34,0)),"") | U8: =IFERROR(INT(AGGREGATE(15,6,'05_MILESTONES'!$M$5:$M$34/('05_MILESTONES'!$B$5:$B$34=$C8),1)),"") | V8: =IF(C8="","",IF(M8="Completed","Closed",IF(M8="Cancelled","N/A",IF(N8="Red","Critical",IF(OR(N8="Yellow",AND(Q8<>"",O8<>"",Q8>O8),AND(R8<>"",R8>7)),"Needs Attention","Healthy"))))) | W8: 46300 | X8: SAMPLE - paused pending content approval. | Y8: =IF(C8="","",COUNTIF($C$5:$C8,"?*")) | Z8: =IF(OR(C8="",N8<>"Red"),"",COUNTIF($N$5:$N$34,"Red")-COUNTIF($N$5:$N8,"Red")+1) | AA8: =IF(C8="","",IF(AND(OR('01_EXECUTIVE_DASHBOARD'!$C$42="All",'01_EXECUTIVE_DASHBOARD'!$C$42=$M8),OR('01_EXECUTIVE_DASHBOARD'!$F$42="All",'01_EXECUTIVE_DASHBOARD'!$F$42=$N8),OR('01_EXECUTIVE_DASHBOARD'!$I$42="All",'01_EXECUTIVE_DASHBOARD'!$I$42=$D8)),SUMPRODUCT(($C$5:$C8<>"")*((('01_EXECUTIVE_DASHBOARD'!$C$42="All")+($M$5:$M8='01_EXECUTIVE_DASHBOARD'!$C$42))>0)*((('01_EXECUTIVE_DASHBOARD'!$F$42="All")+($N$5:$N8='01_EXECUTIVE_DASHBOARD'!$F$42))>0)*((('01_EXECUTIVE_DASHBOARD'!$I$42="All")+($D$5:$D8='01_EXECUTIVE_DASHBOARD'!$I$42))>0)),"")) | AB8: =IF(C8="","",TEXT(H8,"dd-mmm-yy")&" - "&TEXT(IF(K8<>"",K8,J8),"dd-mmm-yy")) | AC8: =IF(C8="","",TEXT(O8,"#,##0")&" / "&TEXT(P8,"#,##0"))
A9: PRJ-005 | B9: Internal | C9: Office Security Upgrade | D9: Tom Becker | E9: Operations | F9: Infrastructure | G9: Medium | H9: 46280 | I9: 46371 | J9: 46371 | L9: 0.15 | M9: Active | N9: Green | O9: 60000 | P9: 9000 | Q9: 60000 | R9: =IF(OR(I9="",J9=""),"",J9-I9) | S9: =IF(OR(O9="",P9=""),"",O9-P9) | T9: =IFERROR(INDEX('05_MILESTONES'!$C$5:$C$34,MATCH(AGGREGATE(15,6,'05_MILESTONES'!$M$5:$M$34/('05_MILESTONES'!$B$5:$B$34=$C9),1),'05_MILESTONES'!$M$5:$M$34,0)),"") | U9: =IFERROR(INT(AGGREGATE(15,6,'05_MILESTONES'!$M$5:$M$34/('05_MILESTONES'!$B$5:$B$34=$C9),1)),"") | V9: =IF(C9="","",IF(M9="Completed","Closed",IF(M9="Cancelled","N/A",IF(N9="Red","Critical",IF(OR(N9="Yellow",AND(Q9<>"",O9<>"",Q9>O9),AND(R9<>"",R9>7)),"Needs Attention","Healthy"))))) | W9: 46301 | X9: SAMPLE - small works package. | Y9: =IF(C9="","",COUNTIF($C$5:$C9,"?*")) | Z9: =IF(OR(C9="",N9<>"Red"),"",COUNTIF($N$5:$N$34,"Red")-COUNTIF($N$5:$N9,"Red")+1) | AA9: =IF(C9="","",IF(AND(OR('01_EXECUTIVE_DASHBOARD'!$C$42="All",'01_EXECUTIVE_DASHBOARD'!$C$42=$M9),OR('01_EXECUTIVE_DASHBOARD'!$F$42="All",'01_EXECUTIVE_DASHBOARD'!$F$42=$N9),OR('01_EXECUTIVE_DASHBOARD'!$I$42="All",'01_EXECUTIVE_DASHBOARD'!$I$42=$D9)),SUMPRODUCT(($C$5:$C9<>"")*((('01_EXECUTIVE_DASHBOARD'!$C$42="All")+($M$5:$M9='01_EXECUTIVE_DASHBOARD'!$C$42))>0)*((('01_EXECUTIVE_DASHBOARD'!$F$42="All")+($N$5:$N9='01_EXECUTIVE_DASHBOARD'!$F$42))>0)*((('01_EXECUTIVE_DASHBOARD'!$I$42="All")+($D$5:$D9='01_EXECUTIVE_DASHBOARD'!$I$42))>0)),"")) | AB9: =IF(C9="","",TEXT(H9,"dd-mmm-yy")&" - "&TEXT(IF(K9<>"",K9,J9),"dd-mmm-yy")) | AC9: =IF(C9="","",TEXT(O9,"#,##0")&" / "&TEXT(P9,"#,##0"))
A10: PRJ-006 | B10: SELAMU SEGARO | C10: Payroll Reporting Portal | D10: Priya Raman | E10: Finance | F10: Development | G10: Medium | H10: 46113 | I10: 46295 | J10: 46295 | K10: 46293 | L10: 1 | M10: Completed | N10: Green | O10: 95000 | P10: 92000 | Q10: 92000 | R10: =IF(OR(I10="",J10=""),"",J10-I10) | S10: =IF(OR(O10="",P10=""),"",O10-P10) | T10: =IFERROR(INDEX('05_MILESTONES'!$C$5:$C$34,MATCH(AGGREGATE(15,6,'05_MILESTONES'!$M$5:$M$34/('05_MILESTONES'!$B$5:$B$34=$C10),1),'05_MILESTONES'!$M$5:$M$34,0)),"") | U10: =IFERROR(INT(AGGREGATE(15,6,'05_MILESTONES'!$M$5:$M$34/('05_MILESTONES'!$B$5:$B$34=$C10),1)),"") | V10: =IF(C10="","",IF(M10="Completed","Closed",IF(M10="Cancelled","N/A",IF(N10="Red","Critical",IF(OR(N10="Yellow",AND(Q10<>"",O10<>"",Q10>O10),AND(R10<>"",R10>7)),"Needs Attention","Healthy"))))) | W10: 46296 | X10: SAMPLE - closed, ready for closure checklist. | Y10: =IF(C10="","",COUNTIF($C$5:$C10,"?*")) | Z10: =IF(OR(C10="",N10<>"Red"),"",COUNTIF($N$5:$N$34,"Red")-COUNTIF($N$5:$N10,"Red")+1) | AA10: =IF(C10="","",IF(AND(OR('01_EXECUTIVE_DASHBOARD'!$C$42="All",'01_EXECUTIVE_DASHBOARD'!$C$42=$M10),OR('01_EXECUTIVE_DASHBOARD'!$F$42="All",'01_EXECUTIVE_DASHBOARD'!$F$42=$N10),OR('01_EXECUTIVE_DASHBOARD'!$I$42="All",'01_EXECUTIVE_DASHBOARD'!$I$42=$D10)),SUMPRODUCT(($C$5:$C10<>"")*((('01_EXECUTIVE_DASHBOARD'!$C$42="All")+($M$5:$M10='01_EXECUTIVE_DASHBOARD'!$C$42))>0)*((('01_EXECUTIVE_DASHBOARD'!$F$42="All")+($N$5:$N10='01_EXECUTIVE_DASHBOARD'!$F$42))>0)*((('01_EXECUTIVE_DASHBOARD'!$I$42="All")+($D$5:$D10='01_EXECUTIVE_DASHBOARD'!$I$42))>0)),"")) | AB10: =IF(C10="","",TEXT(H10,"dd-mmm-yy")&" - "&TEXT(IF(K10<>"",K10,J10),"dd-mmm-yy")) | AC10: =IF(C10="","",TEXT(O10,"#,##0")&" / "&TEXT(P10,"#,##0"))
A11: PRJ-007 | B11: Internal | C11: Legacy Fax System Decommission | D11: Tom Becker | E11: IT | F11: Maintenance | G11: Low | H11: 46174 | I11: 46265 | J11: 46265 | L11: 0.1 | M11: Cancelled | N11: Red | O11: 25000 | P11: 4000 | Q11: 4000 | R11: =IF(OR(I11="",J11=""),"",J11-I11) | S11: =IF(OR(O11="",P11=""),"",O11-P11) | T11: =IFERROR(INDEX('05_MILESTONES'!$C$5:$C$34,MATCH(AGGREGATE(15,6,'05_MILESTONES'!$M$5:$M$34/('05_MILESTONES'!$B$5:$B$34=$C11),1),'05_MILESTONES'!$M$5:$M$34,0)),"") | U11: =IFERROR(INT(AGGREGATE(15,6,'05_MILESTONES'!$M$5:$M$34/('05_MILESTONES'!$B$5:$B$34=$C11),1)),"") | V11: =IF(C11="","",IF(M11="Completed","Closed",IF(M11="Cancelled","N/A",IF(N11="Red","Critical",IF(OR(N11="Yellow",AND(Q11<>"",O11<>"",Q11>O11),AND(R11<>"",R11>7)),"Needs Attention","Healthy"))))) | W11: 46254 | X11: SAMPLE - cancelled, superseded by network upgrade. | Y11: =IF(C11="","",COUNTIF($C$5:$C11,"?*")) | Z11: =IF(OR(C11="",N11<>"Red"),"",COUNTIF($N$5:$N$34,"Red")-COUNTIF($N$5:$N11,"Red")+1) | AA11: =IF(C11="","",IF(AND(OR('01_EXECUTIVE_DASHBOARD'!$C$42="All",'01_EXECUTIVE_DASHBOARD'!$C$42=$M11),OR('01_EXECUTIVE_DASHBOARD'!$F$42="All",'01_EXECUTIVE_DASHBOARD'!$F$42=$N11),OR('01_EXECUTIVE_DASHBOARD'!$I$42="All",'01_EXECUTIVE_DASHBOARD'!$I$42=$D11)),SUMPRODUCT(($C$5:$C11<>"")*((('01_EXECUTIVE_DASHBOARD'!$C$42="All")+($M$5:$M11='01_EXECUTIVE_DASHBOARD'!$C$42))>0)*((('01_EXECUTIVE_DASHBOARD'!$F$42="All")+($N$5:$N11='01_EXECUTIVE_DASHBOARD'!$F$42))>0)*((('01_EXECUTIVE_DASHBOARD'!$I$42="All")+($D$5:$D11='01_EXECUTIVE_DASHBOARD'!$I$42))>0)),"")) | AB11: =IF(C11="","",TEXT(H11,"dd-mmm-yy")&" - "&TEXT(IF(K11<>"",K11,J11),"dd-mmm-yy")) | AC11: =IF(C11="","",TEXT(O11,"#,##0")&" / "&TEXT(P11,"#,##0"))
